Workbook

Sheet FOUND DATA
A1: IF YOU HAVE A COURSE THAT YOU CAN NOT FIND THE SYLLABUS FOR, PLEASE ADD IT TO THE OTHER SHEET
B2: BLUE - UD | C2: ORANGE - UT | D2: RED - UWM
B3: FEATURES | N3: OUTPUTS (% Of Students in Each Bucket) | T3: PASS FAIL | W3: PASS (IN DEPTH) | Z3: RANKING (1 = Least students, 5 = Most students)
A4: Course Code | B4: # HWs | C4: HW Weight | D4: # Project Assignments | E4: Project Weight | F4: # Final exam | G4: Final Weight | H4: # Other Exams | I4: Exam Weight | J4: # Quizzes | K4: Quiz Weight | L4: Attend/Misc Weight | M4: TOTAL SUM (CHECK THAT IT'S 1) | N4: Class F | O4: Class D | P4: Class C | Q4: Class B | R4: Class A | S4: TOTAL SUM % (CHECK THAT IT'S 100%) | T4: % FAIL | U4: % PASS | V4: SUM (CHECK) | W4: FAIL (D,F) | X4: CLOSE PASS (C) | Y4: CLEAR PASS (A,B) | Z4: F | AA4: D | AB4: C | AC4: B | AD4: A
A5: UD Class 1 | B5: 5 | C5: 0.2 | D5: 10 | E5: 0.6 | F5: 0 | G5: 0 | H5: 0 | I5: 0 | J5: 30 | K5: 0.2 | L5: 0 | M5: =sum(C5+E5+G5+I5+K5+L5) -> 1 | N5: 0.48 | O5: 1.58 | P5: 4.11 | Q5: 15.03 | R5: 78.8 | S5: =SUM(N5:R5) -> 100 | T5: =SUM(N5:O5) -> 2.06 | U5: =SUM(P5:R5) -> 97.94 | V5: =SUM(T5:U5) -> 100 | W5: =SUM(N5:O5) -> 2.06 | X5: =P5 -> 4.11 | Y5: =SUM(Q5:R5) -> 93.83 | Z5: =_xlfn.RANK.EQ(N5,$N5:$R5, 1) -> 1 | AA5: =_xlfn.RANK.EQ(O5,$N5:$R5, 1) -> 2 | AB5: =_xlfn.RANK.EQ(P5,$N5:$R5, 1) -> 3 | AC5: =_xlfn.RANK.EQ(Q5,$N5:$R5, 1) -> 4 | AD5: =_xlfn.RANK.EQ(R5,$N5:$R5, 1) -> 5
A6: UD Class 2 | B6: 8 | C6: 0.32 | D6: 4 | E6: 0.16 | F6: 1 | G6: 0.2 | H6: 0 | I6: 0 | J6: 4 | K6: 0.32 | L6: 0 | M6: =sum(C6+E6+G6+I6+K6+L6) -> 1 | N6: 1.2 | O6: 4.82 | P6: 19.28 | Q6: 39.76 | R6: 34.94 | S6: =SUM(N6:R6) -> 100 | T6: =SUM(N6:O6) -> 6.02 | U6: =SUM(P6:R6) -> 93.98 | V6: =SUM(T6:U6) -> 100 | W6: =SUM(N6:O6) -> 6.02 | X6: =P6 -> 19.28 | Y6: =SUM(Q6:R6) -> 74.7 | Z6: =_xlfn.RANK.EQ(N6,$N6:$R6, 1) -> 1 | AA6: =_xlfn.RANK.EQ(O6,$N6:$R6, 1) -> 2 | AB6: =_xlfn.RANK.EQ(P6,$N6:$R6, 1) -> 3 | AC6: =_xlfn.RANK.EQ(Q6,$N6:$R6, 1) -> 5 | AD6: =_xlfn.RANK.EQ(R6,$N6:$R6, 1) -> 4
A7: UD Class 3 | B7: 8 | C7: 0.32 | D7: 4 | E7: 0.16 | F7: 1 | G7: 0.2 | H7: 0 | I7: 0 | J7: 4 | K7: 0.32 | L7: 0 | M7: =sum(C7+E7+G7+I7+K7+L7) -> 1 | N7: 0 | O7: 5.97 | P7: 16.42 | Q7: 41.79 | R7: 35.82 | S7: =SUM(N7:R7) -> 100 | T7: =SUM(N7:O7) -> 5.97 | U7: =SUM(P7:R7) -> 94.03 | V7: =SUM(T7:U7) -> 100 | W7: =SUM(N7:O7) -> 5.97 | X7: =P7 -> 16.42 | Y7: =SUM(Q7:R7) -> 77.61 | Z7: =_xlfn.RANK.EQ(N7,$N7:$R7, 1) -> 1 | AA7: =_xlfn.RANK.EQ(O7,$N7:$R7, 1) -> 2 | AB7: =_xlfn.RANK.EQ(P7,$N7:$R7, 1) -> 3 | AC7: =_xlfn.RANK.EQ(Q7,$N7:$R7, 1) -> 5 | AD7: =_xlfn.RANK.EQ(R7,$N7:$R7, 1) -> 4
A8: UD Class 4 | B8: 8 | C8: 0.3 | D8: 6 | E8: 0.2 | F8: 0 | G8: 0 | H8: 3 | I8: 0.45 | J8: 0 | K8: 0 | L8: 0.05 | M8: =sum(C8+E8+G8+I8+K8+L8) -> 1 | N8: 3.17 | O8: 6.35 | P8: 16.67 | Q8: 48.41 | R8: 25.4 | S8: =SUM(N8:R8) -> 100 | T8: =SUM(N8:O8) -> 9.52 | U8: =SUM(P8:R8) -> 90.48 | V8: =SUM(T8:U8) -> 100 | W8: =SUM(N8:O8) -> 9.52 | X8: =P8 -> 16.67 | Y8: =SUM(Q8:R8) -> 73.81 | Z8: =_xlfn.RANK.EQ(N8,$N8:$R8, 1) -> 1 | AA8: =_xlfn.RANK.EQ(O8,$N8:$R8, 1) -> 2 | AB8: =_xlfn.RANK.EQ(P8,$N8:$R8, 1) -> 3 | AC8: =_xlfn.RANK.EQ(Q8,$N8:$R8, 1) -> 5 | AD8: =_xlfn.RANK.EQ(R8,$N8:$R8, 1) -> 4
A9: UD Class 5 | B9: 16 | C9: 0.5 | D9: 6 | E9: 0.2 | F9: 0 | G9: 0 | H9: 3 | I9: 0.3 | J9: 0 | K9: 0 | L9: 0 | M9: =sum(C9+E9+G9+I9+K9+L9) -> 1 | N9: 3.43 | O9: 2.05 | P9: 32.19 | Q9: 45.21 | R9: 17.12 | S9: =SUM(N9:R9) -> 100 | T9: =SUM(N9:O9) -> 5.48 | U9: =SUM(P9:R9) -> 94.52 | V9: =SUM(T9:U9) -> 100 | W9: =SUM(N9:O9) -> 5.48 | X9: =P9 -> 32.19 | Y9: =SUM(Q9:R9) -> 62.33 | Z9: =_xlfn.RANK.EQ(N9,$N9:$R9, 1) -> 2 | AA9: =_xlfn.RANK.EQ(O9,$N9:$R9, 1) -> 1 | AB9: =_xlfn.RANK.EQ(P9,$N9:$R9, 1) -> 4 | AC9: =_xlfn.RANK.EQ(Q9,$N9:$R9, 1) -> 5 | AD9: =_xlfn.RANK.EQ(R9,$N9:$R9, 1) -> 3
A10: UD Class 6 | B10: 9 | C10: 0.36 | D10: 0 | E10: 0 | F10: 0 | G10: 0 | H10: 4 | I10: 0.48 | J10: 35 | K10: 0.16 | L10: 0 | M10: =sum(C10+E10+G10+I10+K10+L10) -> 1 | N10: 5.63 | O10: 3.52 | P10: 17.61 | Q10: 39.44 | R10: 33.8 | S10: =SUM(N10:R10) -> 100 | T10: =SUM(N10:O10) -> 9.15 | U10: =SUM(P10:R10) -> 90.85 | V10: =SUM(T10:U10) -> 100 | W10: =SUM(N10:O10) -> 9.15 | X10: =P10 -> 17.61 | Y10: =SUM(Q10:R10) -> 73.24 | Z10: =_xlfn.RANK.EQ(N10,$N10:$R10, 1) -> 2 | AA10: =_xlfn.RANK.EQ(O10,$N10:$R10, 1) -> 1 | AB10: =_xlfn.RANK.EQ(P10,$N10:$R10, 1) -> 3 | AC10: =_xlfn.RANK.EQ(Q10,$N10:$R10, 1) -> 5 | AD10: =_xlfn.RANK.EQ(R10,$N10:$R10, 1) -> 4
A11: UD Class 7 | B11: 11 | C11: 0.25 | D11: 5 | E11: 0.15 | F11: 1 | G11: 0.2 | H11: 3 | I11: 0.3 | J11: 0 | K11: 0 | L11: 0.1 | M11: =sum(C11+E11+G11+I11+K11+L11) -> 1 | N11: 5.36 | O11: 6.55 | P11: 19.64 | Q11: 35.12 | R11: 33.33 | S11: =SUM(N11:R11) -> 100 | T11: =SUM(N11:O11) -> 11.91 | U11: =SUM(P11:R11) -> 88.09 | V11: =SUM(T11:U11) -> 100 | W11: =SUM(N11:O11) -> 11.91 | X11: =P11 -> 19.64 | Y11: =SUM(Q11:R11) -> 68.45 | Z11: =_xlfn.RANK.EQ(N11,$N11:$R11, 1) -> 1 | AA11: =_xlfn.RANK.EQ(O11,$N11:$R11, 1) -> 2 | AB11: =_xlfn.RANK.EQ(P11,$N11:$R11, 1) -> 3 | AC11: =_xlfn.RANK.EQ(Q11,$N11:$R11, 1) -> 5 | AD11: =_xlfn.RANK.EQ(R11,$N11:$R11, 1) -> 4
A12: UD Class 8 | B12: 11 | C12: 0.25 | D12: 4 | E12: 0.15 | F12: 1 | G12: 0.2 | H12: 3 | I12: 0.3 | J12: 24 | K12: 0.1 | L12: 0 | M12: =sum(C12+E12+G12+I12+K12+L12) -> 1 | N12: 7.5 | O12: 6.25 | P12: 22.5 | Q12: 34.38 | R12: 29.37 | S12: =SUM(N12:R12) -> 100 | T12: =SUM(N12:O12) -> 13.75 | U12: =SUM(P12:R12) -> 86.25 | V12: =SUM(T12:U12) -> 100 | W12: =SUM(N12:O12) -> 13.75 | X12: =P12 -> 22.5 | Y12: =SUM(Q12:R12) -> 63.75 | Z12: =_xlfn.RANK.EQ(N12,$N12:$R12, 1) -> 2 | AA12: =_xlfn.RANK.EQ(O12,$N12:$R12, 1) -> 1 | AB12: =_xlfn.RANK.EQ(P12,$N12:$R12, 1) -> 3 | AC12: =_xlfn.RANK.EQ(Q12,$N12:$R12, 1) -> 5 | AD12: =_xlfn.RANK.EQ(R12,$N12:$R12, 1) -> 4
A13: UD Class 9 | B13: 10 | C13: 0.25 | D13: 9 | E13: 0.15 | F13: 1 | G13: 0.2 | H13: 3 | I13: 0.3 | J13: 25 | K13: 0.1 | L13: 0 | M13: =sum(C13+E13+G13+I13+K13+L13) -> 1 | N13: 7.1 | O13: 7.1 | P13: 12.26 | Q13: 34.19 | R13: 39.35 | S13: =SUM(N13:R13) -> 100 | T13: =SUM(N13:O13) -> 14.2 | U13: =SUM(P13:R13) -> 85.8 | V13: =SUM(T13:U13) -> 100 | W13: =SUM(N13:O13) -> 14.2 | X13: =P13 -> 12.26 | Y13: =SUM(Q13:R13) -> 73.54 | Z13: =_xlfn.RANK.EQ(N13,$N13:$R13, 1) -> 1 | AA13: =_xlfn.RANK.EQ(O13,$N13:$R13, 1) -> 1 | AB13: =_xlfn.RANK.EQ(P13,$N13:$R13, 1) -> 3 | AC13: =_xlfn.RANK.EQ(Q13,$N13:$R13, 1) -> 4 | AD13: =_xlfn.RANK.EQ(R13,$N13:$R13, 1) -> 5
A14: UD Class 10 | B14: 10 | C14: 0.25 | D14: 6 | E14: 0.15 | F14: 1 | G14: 0.2 | H14: 3 | I14: 0.3 | J14: 24 | K14: 0.1 | L14: 0 | M14: =sum(C14+E14+G14+I14+K14+L14) -> 1 | N14: 6.56 | O14: 2.19 | P14: 10.95 | Q14: 35.77 | R14: 44.53 | S14: =SUM(N14:R14) -> 100 | T14: =SUM(N14:O14) -> 8.75 | U14: =SUM(P14:R14) -> 91.25 | V14: =SUM(T14:U14) -> 100 | W14: =SUM(N14:O14) -> 8.75 | X14: =P14 -> 10.95 | Y14: =SUM(Q14:R14) -> 80.3 | Z14: =_xlfn.RANK.EQ(N14,$N14:$R14, 1) -> 2 | AA14: =_xlfn.RANK.EQ(O14,$N14:$R14, 1) -> 1 | AB14: =_xlfn.RANK.EQ(P14,$N14:$R14, 1) -> 3 | AC14: =_xlfn.RANK.EQ(Q14,$N14:$R14, 1) -> 4 | AD14: =_xlfn.RANK.EQ(R14,$N14:$R14, 1) -> 5
A15: UD Class 11 | B15: 10 | C15: 0.25 | D15: 1 | E15: 0.1 | F15: 1 | G15: 0.2 | H15: 3 | I15: 0.3 | J15: 24 | K15: 0.15 | L15: 0 | M15: =sum(C15+E15+G15+I15+K15+L15) -> 1 | N15: 1.55 | O15: 0.78 | P15: 17.83 | Q15: 41.86 | R15: 37.98 | S15: =SUM(N15:R15) -> 100 | T15: =SUM(N15:O15) -> 2.33 | U15: =SUM(P15:R15) -> 97.67 | V15: =SUM(T15:U15) -> 100 | W15: =SUM(N15:O15) -> 2.33 | X15: =P15 -> 17.83 | Y15: =SUM(Q15:R15) -> 79.84 | Z15: =_xlfn.RANK.EQ(N15,$N15:$R15, 1) -> 2 | AA15: =_xlfn.RANK.EQ(O15,$N15:$R15, 1) -> 1 | AB15: =_xlfn.RANK.EQ(P15,$N15:$R15, 1) -> 3 | AC15: =_xlfn.RANK.EQ(Q15,$N15:$R15, 1) -> 5 | AD15: =_xlfn.RANK.EQ(R15,$N15:$R15, 1) -> 4
A16: UD Class 12 | B16: 10 | C16: 0.25 | D16: 1 | E16: 0.1 | F16: 1 | G16: 0.2 | H16: 3 | I16: 0.3 | J16: 28 | K16: 0.15 | L16: 0 | M16: =sum(C16+E16+G16+I16+K16+L16) -> 1 | N16: 3.85 | O16: 3.08 | P16: 13.07 | Q16: 40 | R16: 40 | S16: =SUM(N16:R16) -> 100 | T16: =SUM(N16:O16) -> 6.93 | U16: =SUM(P16:R16) -> 93.07 | V16: =SUM(T16:U16) -> 100 | W16: =SUM(N16:O16) -> 6.93 | X16: =P16 -> 13.07 | Y16: =SUM(Q16:R16) -> 80 | Z16: =_xlfn.RANK.EQ(N16,$N16:$R16, 1) -> 2 | AA16: =_xlfn.RANK.EQ(O16,$N16:$R16, 1) -> 1 | AB16: =_xlfn.RANK.EQ(P16,$N16:$R16, 1) -> 3 | AC16: =_xlfn.RANK.EQ(Q16,$N16:$R16, 1) -> 4 | AD16: =_xlfn.RANK.EQ(R16,$N16:$R16, 1) -> 4
... A36: CE329 - 16S | B36: 13 | C36: 0.27 | D36: 0 | E36: 0 | F36: 1 | G36: 0.3 | H36: 2 | I36: 0.38 | J36: 0 | K36: 0 | L36: 0.05 | M36: =sum(C36+E36+G36+I36+K36+L36) -> 1 | N36: 3.57 | O36: 3.57 | P36: 17.86 | Q36: 32.14 | R36: 42.86 | S36: =SUM(N36:R36) -> 100 | T36: =SUM(N36:O36) -> 7.14 | U36: =SUM(P36:R36) -> 92.86 | V36: =SUM(T36:U36) -> 100 | W36: =SUM(N36:O36) -> 7.14 | X36: =P36 -> 17.86 | Y36: =SUM(Q36:R36) -> 75 | Z36: =_xlfn.RANK.EQ(N36,$N36:$R36, 1) -> 1 | AA36: =_xlfn.RANK.EQ(O36,$N36:$R36, 1) -> 1 | AB36: =_xlfn.RANK.EQ(P36,$N36:$R36, 1) -> 3 | AC36: =_xlfn.RANK.EQ(Q36,$N36:$R36, 1) -> 4 | AD36: =_xlfn.RANK.EQ(R36,$N36:$R36, 1) -> 5
A37: COE347 - 18S Bisetti Sec 12875 | B37: 12 | C37: 0.4 | D37: 2 | E37: 0.3 | F37: 0 | G37: 0 | H37: 2 | I37: 0.3 | J37: 0 | K37: 0 | L37: 0 | M37: =sum(C37+E37+G37+I37+K37+L37) -> 1 | N37: 0 | O37: =100*1/24 -> 4.1666667 | P37: 0 | Q37: =100*10/24 -> 41.666667 | R37: =100*13/24 -> 54.166667 | S37: =SUM(N37:R37) -> 100 | T37: =SUM(N37:O37) -> 4.1666667 | U37: =SUM(P37:R37) -> 95.833333 | V37: =SUM(T37:U37) -> 100 | W37: =SUM(N37:O37) -> 4.1666667 | X37: =P37 -> 0 | Y37: =SUM(Q37:R37) -> 95.833333 | Z37: =_xlfn.RANK.EQ(N37,$N37:$R37, 1) -> 1 | AA37: =_xlfn.RANK.EQ(O37,$N37:$R37, 1) -> 3 | AB37: =_xlfn.RANK.EQ(P37,$N37:$R37, 1) -> 1 | AC37: =_xlfn.RANK.EQ(Q37,$N37:$R37, 1) -> 4 | AD37: =_xlfn.RANK.EQ(R37,$N37:$R37, 1) -> 5
A38: COE311K - 23F - Loveland Sec 15065 | B38: 5 | C38: 0.5 | D38: 0 | E38: 0 | F38: 0 | G38: 0 | H38: 2 | I38: 0.5 | J38: 0 | K38: 0 | L38: 0 | M38: =sum(C38+E38+G38+I38+K38+L38) -> 1 | N38: =100*1/(36+14+11+1) -> 1.6129032 | O38: =100*0/(36+14+11+1) -> 0 | P38: =100*11/(36+14+11+1) -> 17.741935 | Q38: =100*14/(36+14+11+1) -> 22.580645 | R38: =100*36/(36+14+11+1) -> 58.064516 | S38: =SUM(N38:R38) -> 100 | T38: =SUM(N38:O38) -> 1.6129032 | U38: =SUM(P38:R38) -> 98.387097 | V38: =SUM(T38:U38) -> 100 | W38: =SUM(N38:O38) -> 1.6129032 | X38: =P38 -> 17.741935 | Y38: =SUM(Q38:R38) -> 80.645161 | Z38: =_xlfn.RANK.EQ(N38,$N38:$R38, 1) -> 2 | AA38: =_xlfn.RANK.EQ(O38,$N38:$R38, 1) -> 1 | AB38: =_xlfn.RANK.EQ(P38,$N38:$R38, 1) -> 3 | AC38: =_xlfn.RANK.EQ(Q38,$N38:$R38, 1) -> 4 | AD38: =_xlfn.RANK.EQ(R38,$N38:$R38, 1) -> 5
A39: COE322 - 23F | B39: 21 | C39: 0.7 | D39: 1 | E39: 0.3 | F39: 0 | G39: 0 | H39: 0 | I39: 0 | J39: 0 | K39: 0 | L39: 0 | M39: =sum(C39+E39+G39+I39+K39+L39) -> 1 | N39: 3.77 | O39: 1.89 | P39: 3.77 | Q39: 15.09 | R39: 75.48 | S39: =SUM(N39:R39) -> 100 | T39: =SUM(N39:O39) -> 5.66 | U39: =SUM(P39:R39) -> 94.34 | V39: =SUM(T39:U39) -> 100 | W39: =SUM(N39:O39) -> 5.66 | X39: =P39 -> 3.77 | Y39: =SUM(Q39:R39) -> 90.57 | Z39: =_xlfn.RANK.EQ(N39,$N39:$R39, 1) -> 2 | AA39: =_xlfn.RANK.EQ(O39,$N39:$R39, 1) -> 1 | AB39: =_xlfn.RANK.EQ(P39,$N39:$R39, 1) -> 2 | AC39: =_xlfn.RANK.EQ(Q39,$N39:$R39, 1) -> 4 | AD39: =_xlfn.RANK.EQ(R39,$N39:$R39, 1) -> 5
A40: CS303 - 22F - 001 | B40: 15 | C40: 0.15 | D40: 3 | E40: 0.3 | F40: 1 | G40: 0.2 | H40: 1 | I40: 0.2 | J40: 6 | K40: 0.15 | L40: 0 | M40: =sum(C40+E40+G40+I40+K40+L40) -> 1 | N40: 5.37 | O40: 5.37 | P40: 8.72 | Q40: 26.85 | R40: 53.69 | S40: =SUM(N40:R40) -> 100 | T40: =SUM(N40:O40) -> 10.74 | U40: =SUM(P40:R40) -> 89.26 | V40: =SUM(T40:U40) -> 100 | W40: =SUM(N40:O40) -> 10.74 | X40: =P40 -> 8.72 | Y40: =SUM(Q40:R40) -> 80.54 | Z40: =_xlfn.RANK.EQ(N40,$N40:$R40, 1) -> 1 | AA40: =_xlfn.RANK.EQ(O40,$N40:$R40, 1) -> 1 | AB40: =_xlfn.RANK.EQ(P40,$N40:$R40, 1) -> 3 | AC40: =_xlfn.RANK.EQ(Q40,$N40:$R40, 1) -> 4 | AD40: =_xlfn.RANK.EQ(R40,$N40:$R40, 1) -> 5
A41: CS303 - 22F - 002 | B41: 15 | C41: 0.15 | D41: 3 | E41: 0.3 | F41: 1 | G41: 0.2 | H41: 1 | I41: 0.2 | J41: 6 | K41: 0.15 | L41: 0 | M41: =sum(C41+E41+G41+I41+K41+L41) -> 1 | N41: 3.21 | O41: 1.92 | P41: 10.9 | Q41: 26.28 | R41: 57.69 | S41: =SUM(N41:R41) -> 100 | T41: =SUM(N41:O41) -> 5.13 | U41: =SUM(P41:R41) -> 94.87 | V41: =SUM(T41:U41) -> 100 | W41: =SUM(N41:O41) -> 5.13 | X41: =P41 -> 10.9 | Y41: =SUM(Q41:R41) -> 83.97 | Z41: =_xlfn.RANK.EQ(N41,$N41:$R41, 1) -> 2 | AA41: =_xlfn.RANK.EQ(O41,$N41:$R41, 1) -> 1 | AB41: =_xlfn.RANK.EQ(P41,$N41:$R41, 1) -> 3 | AC41: =_xlfn.RANK.EQ(Q41,$N41:$R41, 1) -> 4 | AD41: =_xlfn.RANK.EQ(R41,$N41:$R41, 1) -> 5
A42: CS303 - 22F - 003 | B42: 15 | C42: 0.15 | D42: 3 | E42: 0.3 | F42: 1 | G42: 0.2 | H42: 1 | I42: 0.2 | J42: 6 | K42: 0.15 | L42: 0 | M42: =sum(C42+E42+G42+I42+K42+L42) -> 1 | N42: 6.54 | O42: 2.61 | P42: 15.03 | Q42: 17.65 | R42: 58.17 | S42: =SUM(N42:R42) -> 100 | T42: =SUM(N42:O42) -> 9.15 | U42: =SUM(P42:R42) -> 90.85 | V42: =SUM(T42:U42) -> 100 | W42: =SUM(N42:O42) -> 9.15 | X42: =P42 -> 15.03 | Y42: =SUM(Q42:R42) -> 75.82 | Z42: =_xlfn.RANK.EQ(N42,$N42:$R42, 1) -> 2 | AA42: =_xlfn.RANK.EQ(O42,$N42:$R42, 1) -> 1 | AB42: =_xlfn.RANK.EQ(P42,$N42:$R42, 1) -> 3 | AC42: =_xlfn.RANK.EQ(Q42,$N42:$R42, 1) -> 4 | AD42: =_xlfn.RANK.EQ(R42,$N42:$R42, 1) -> 5
A43: CS314 HONORS - 22F | B43: 7 | C43: 0.5 | D43: 0 | E43: 0 | F43: 1 | G43: 0.3 | H43: 1 | I43: 0.2 | J43: 0 | K43: 0 | L43: 0 | M43: =sum(C43+E43+G43+I43+K43+L43) -> 1 | N43: 0 | O43: 2.5 | P43: 7.5 | Q43: 40 | R43: 50 | S43: =SUM(N43:R43) -> 100 | T43: =SUM(N43:O43) -> 2.5 | U43: =SUM(P43:R43) -> 97.5 | V43: =SUM(T43:U43) -> 100 | W43: =SUM(N43:O43) -> 2.5 | X43: =P43 -> 7.5 | Y43: =SUM(Q43:R43) -> 90 | Z43: =_xlfn.RANK.EQ(N43,$N43:$R43, 1) -> 1 | AA43: =_xlfn.RANK.EQ(O43,$N43:$R43, 1) -> 2 | AB43: =_xlfn.RANK.EQ(P43,$N43:$R43, 1) -> 3 | AC43: =_xlfn.RANK.EQ(Q43,$N43:$R43, 1) -> 4 | AD43: =_xlfn.RANK.EQ(R43,$N43:$R43, 1) -> 5
A44: CS314 HONORS - 23F | B44: 7 | C44: 0.55 | D44: 0 | E44: 0 | F44: 0 | G44: 0 | H44: 2 | I44: 0.45 | J44: 0 | K44: 0 | L44: 0 | M44: =sum(C44+E44+G44+I44+K44+L44) -> 1 | N44: 0 | O44: 0 | P44: 18.18 | Q44: 36.37 | R44: 45.45 | S44: =SUM(N44:R44) -> 100 | T44: =SUM(N44:O44) -> 0 | U44: =SUM(P44:R44) -> 100 | V44: =SUM(T44:U44) -> 100 | W44: =SUM(N44:O44) -> 0 | X44: =P44 -> 18.18 | Y44: =SUM(Q44:R44) -> 81.82 | Z44: =_xlfn.RANK.EQ(N44,$N44:$R44, 1) -> 1 | AA44: =_xlfn.RANK.EQ(O44,$N44:$R44, 1) -> 1 | AB44: =_xlfn.RANK.EQ(P44,$N44:$R44, 1) -> 3 | AC44: =_xlfn.RANK.EQ(Q44,$N44:$R44, 1) -> 4 | AD44: =_xlfn.RANK.EQ(R44,$N44:$R44, 1) -> 5
A45: CS314 - 23F | B45: 11 | C45: 0.22 | D45: 0 | E45: 0 | F45: 1 | G45: 0.24 | H45: 2 | I45: 0.49 | J45: 10 | K45: 0.05 | L45: 0 | M45: =sum(C45+E45+G45+I45+K45+L45) -> 1 | N45: 2.42 | O45: 5.14 | P45: 18.72 | Q45: 35.35 | R45: 38.37 | S45: =SUM(N45:R45) -> 100 | T45: =SUM(N45:O45) -> 7.56 | U45: =SUM(P45:R45) -> 92.44 | V45: =SUM(T45:U45) -> 100 | W45: =SUM(N45:O45) -> 7.56 | X45: =P45 -> 18.72 | Y45: =SUM(Q45:R45) -> 73.72 | Z45: =_xlfn.RANK.EQ(N45,$N45:$R45, 1) -> 1 | AA45: =_xlfn.RANK.EQ(O45,$N45:$R45, 1) -> 2 | AB45: =_xlfn.RANK.EQ(P45,$N45:$R45, 1) -> 3 | AC45: =_xlfn.RANK.EQ(Q45,$N45:$R45, 1) -> 4 | AD45: =_xlfn.RANK.EQ(R45,$N45:$R45, 1) -> 5
A46: ECE381V - 21F Wang Sec 17035 | B46: 0 | C46: 0 | D46: 4 | E46: 0.6 | F46: 0 | G46: 0 | H46: 0 | I46: 0 | J46: 3 | K46: 0.3 | L46: 0.1 | M46: =sum(C46+E46+G46+I46+K46+L46) -> 1 | N46: 0 | O46: 0 | P46: 0 | Q46: =100/28 -> 3.5714286 | R46: =100*27/28 -> 96.428571 | S46: =SUM(N46:R46) -> 100 | T46: =SUM(N46:O46) -> 0 | U46: =SUM(P46:R46) -> 100 | V46: =SUM(T46:U46) -> 100 | W46: =SUM(N46:O46) -> 0 | X46: =P46 -> 0 | Y46: =SUM(Q46:R46) -> 100 | Z46: =_xlfn.RANK.EQ(N46,$N46:$R46, 1) -> 1 | AA46: =_xlfn.RANK.EQ(O46,$N46:$R46, 1) -> 1 | AB46: =_xlfn.RANK.EQ(P46,$N46:$R46, 1) -> 1 | AC46: =_xlfn.RANK.EQ(Q46,$N46:$R46, 1) -> 4 | AD46: =_xlfn.RANK.EQ(R46,$N46:$R46, 1) -> 5
A47: ECE381V - 21F Harwath Sec 17055 | B47: 11 | C47: 0.6 | D47: 1 | E47: 0.4 | F47: 0 | G47: 0 | H47: 0 | I47: 0 | J47: 0 | K47: 0 | L47: 0 | M47: =sum(C47+E47+G47+I47+K47+L47) -> 1 | N47: 0 | O47: 0 | P47: =1/8*100 -> 12.5 | Q47: =1/8*100 -> 12.5 | R47: =6/8*100 -> 75 | S47: =SUM(N47:R47) -> 100 | T47: =SUM(N47:O47) -> 0 | U47: =SUM(P47:R47) -> 100 | V47: =SUM(T47:U47) -> 100 | W47: =SUM(N47:O47) -> 0 | X47: =P47 -> 12.5 | Y47: =SUM(Q47:R47) -> 87.5 | Z47: =_xlfn.RANK.EQ(N47,$N47:$R47, 1) -> 1 | AA47: =_xlfn.RANK.EQ(O47,$N47:$R47, 1) -> 1 | AB47: =_xlfn.RANK.EQ(P47,$N47:$R47, 1) -> 3 | AC47: =_xlfn.RANK.EQ(Q47,$N47:$R47, 1) -> 3 | AD47: =_xlfn.RANK.EQ(R47,$N47:$R47, 1) -> 5
A48: ECE382N - 21 F Swartzlander Sec 17115 | B48: 15 | C48: 0.05 | D48: 1 | E48: 0.35 | F48: 0 | G48: 0 | H48: 3 | I48: 0.6 | J48: 0 | K48: 0 | L48: 0 | M48: =sum(C48+E48+G48+I48+K48+L48) -> 1 | N48: 0 | O48: 0 | P48: =100/48 -> 2.0833333 | Q48: =100*6/48 -> 12.5 | R48: =100*41/48 -> 85.416667 | S48: =SUM(N48:R48) -> 100 | T48: =SUM(N48:O48) -> 0 | U48: =SUM(P48:R48) -> 100 | V48: =SUM(T48:U48) -> 100 | W48: =SUM(N48:O48) -> 0 | X48: =P48 -> 2.0833333 | Y48: =SUM(Q48:R48) -> 97.916667 | Z48: =_xlfn.RANK.EQ(N48,$N48:$R48, 1) -> 1 | AA48: =_xlfn.RANK.EQ(O48,$N48:$R48, 1) -> 1 | AB48: =_xlfn.RANK.EQ(P48,$N48:$R48, 1) -> 3 | AC48: =_xlfn.RANK.EQ(Q48,$N48:$R48, 1) -> 4 | AD48: =_xlfn.RANK.EQ(R48,$N48:$R48, 1) -> 5
A49: ECE313 - 23F - A. MOKHTARI | B49: 13 | C49: 0.25 | D49: 0 | E49: 0 | F49: 1 | G49: 0.35 | H49: 2 | I49: 0.4 | J49: 0 | K49: 0 | L49: 0 | M49: =sum(C49+E49+G49+I49+K49+L49) -> 1 | N49: 6.06 | O49: 18.18 | P49: 24.24 | Q49: 18.18 | R49: 33.34 | S49: =SUM(N49:R49) -> 100 | T49: =SUM(N49:O49) -> 24.24 | U49: =SUM(P49:R49) -> 75.76 | V49: =SUM(T49:U49) -> 100 | W49: =SUM(N49:O49) -> 24.24 | X49: =P49 -> 24.24 | Y49: =SUM(Q49:R49) -> 51.52 | Z49: =_xlfn.RANK.EQ(N49,$N49:$R49, 1) -> 1 | AA49: =_xlfn.RANK.EQ(O49,$N49:$R49, 1) -> 2 | AB49: =_xlfn.RANK.EQ(P49,$N49:$R49, 1) -> 4 | AC49: =_xlfn.RANK.EQ(Q49,$N49:$R49, 1) -> 2 | AD49: =_xlfn.RANK.EQ(R49,$N49:$R49, 1) -> 5
A50: ECE313 - 23F - A. CUEVAS | B50: 14 | C50: 0.15 | D50: 0 | E50: 0 | F50: 1 | G50: 0.25 | H50: 2 | I50: 0.45 | J50: 42 | K50: 0.1 | L50: 0.05 | M50: =sum(C50+E50+G50+I50+K50+L50) -> 1 | N50: 6.45 | O50: 0 | P50: 22.58 | Q50: 48.39 | R50: 22.58 | S50: =SUM(N50:R50) -> 100 | T50: =SUM(N50:O50) -> 6.45 | U50: =SUM(P50:R50) -> 93.55 | V50: =SUM(T50:U50) -> 100 | W50: =SUM(N50:O50) -> 6.45 | X50: =P50 -> 22.58 | Y50: =SUM(Q50:R50) -> 70.97 | Z50: =_xlfn.RANK.EQ(N50,$N50:$R50, 1) -> 2 | AA50: =_xlfn.RANK.EQ(O50,$N50:$R50, 1) -> 1 | AB50: =_xlfn.RANK.EQ(P50,$N50:$R50, 1) -> 3 | AC50: =_xlfn.RANK.EQ(Q50,$N50:$R50, 1) -> 5 | AD50: =_xlfn.RANK.EQ(R50,$N50:$R50, 1) -> 3
A51: ME338 - 14F | B51: 6 | C51: 0.15 | D51: 5 | E51: 0.3 | F51: 0 | G51: 0 | H51: 3 | I51: 0.45 | J51: 26 | K51: 0.1 | L51: 0 | M51: =sum(C51+E51+G51+I51+K51+L51) -> 1 | N51: 0 | O51: 0 | P51: 0.95 | Q51: 23.81 | R51: 75.24 | S51: =SUM(N51:R51) -> 100 | T51: =SUM(N51:O51) -> 0 | U51: =SUM(P51:R51) -> 100 | V51: =SUM(T51:U51) -> 100 | W51: =SUM(N51:O51) -> 0 | X51: =P51 -> 0.95 | Y51: =SUM(Q51:R51) -> 99.05 | Z51: =_xlfn.RANK.EQ(N51,$N51:$R51, 1) -> 1 | AA51: =_xlfn.RANK.EQ(O51,$N51:$R51, 1) -> 1 | AB51: =_xlfn.RANK.EQ(P51,$N51:$R51, 1) -> 3 | AC51: =_xlfn.RANK.EQ(Q51,$N51:$R51, 1) -> 4 | AD51: =_xlfn.RANK.EQ(R51,$N51:$R51, 1) -> 5
A52: ME344 - 16S | B52: 17 | C52: 0.15 | D52: 0 | E52: 0 | F52: 1 | G52: 0.3 | H52: 2 | I52: 0.5 | J52: 0 | K52: 0 | L52: 0.05 | M52: =sum(C52+E52+G52+I52+K52+L52) -> 1 | N52: 0 | O52: 6.67 | P52: 46.66 | Q52: 10 | R52: 36.67 | S52: =SUM(N52:R52) -> 100 | T52: =SUM(N52:O52) -> 6.67 | U52: =SUM(P52:R52) -> 93.33 | V52: =SUM(T52:U52) -> 100 | W52: =SUM(N52:O52) -> 6.67 | X52: =P52 -> 46.66 | Y52: =SUM(Q52:R52) -> 46.67 | Z52: =_xlfn.RANK.EQ(N52,$N52:$R52, 1) -> 1 | AA52: =_xlfn.RANK.EQ(O52,$N52:$R52, 1) -> 2 | AB52: =_xlfn.RANK.EQ(P52,$N52:$R52, 1) -> 5 | AC52: =_xlfn.RANK.EQ(Q52,$N52:$R52, 1) -> 3 | AD52: =_xlfn.RANK.EQ(R52,$N52:$R52, 1) -> 4
A53: ME374C - 16S Combustion Engine Processes | B53: 8 | C53: 0.3 | D53: 0 | E53: 0 | F53: 1 | G53: 0.3 | H53: 2 | I53: 0.4 | J53: 0 | K53: 0 | L53: 0 | M53: =sum(C53+E53+G53+I53+K53+L53) -> 1 | N53: 0 | O53: =1/(16+8+5+1)*100 -> 3.3333333 | P53: =5/(16+8+5+1)*100 -> 16.666667 | Q53: =8/(16+8+5+1)*100 -> 26.666667 | R53: =16/(16+8+5+1)*100 -> 53.333333 | S53: =SUM(N53:R53) -> 100 | T53: =SUM(N53:O53) -> 3.3333333 | U53: =SUM(P53:R53) -> 96.666667 | V53: =SUM(T53:U53) -> 100 | W53: =SUM(N53:O53) -> 3.3333333 | X53: =P53 -> 16.666667 | Y53: =SUM(Q53:R53) -> 80 | Z53: =_xlfn.RANK.EQ(N53,$N53:$R53, 1) -> 1 | AA53: =_xlfn.RANK.EQ(O53,$N53:$R53, 1) -> 2 | AB53: =_xlfn.RANK.EQ(P53,$N53:$R53, 1) -> 3 | AC53: =_xlfn.RANK.EQ(Q53,$N53:$R53, 1) -> 4 | AD53: =_xlfn.RANK.EQ(R53,$N53:$R53, 1) -> 5
A54: ME334 - 16S - Y. ZHENG | B54: 7 | C54: 0.1 | D54: 0 | E54: 0 | F54: 1 | G54: 0.45 | H54: 2 | I54: 0.4 | J54: 0 | K54: 0 | L54: 0.05 | M54: =sum(C54+E54+G54+I54+K54+L54) -> 1 | N54: 4 | O54: 4 | P54: 14 | Q54: 38 | R54: 40 | S54: =SUM(N54:R54) -> 100 | T54: =SUM(N54:O54) -> 8 | U54: =SUM(P54:R54) -> 92 | V54: =SUM(T54:U54) -> 100 | W54: =SUM(N54:O54) -> 8 | X54: =P54 -> 14 | Y54: =SUM(Q54:R54) -> 78 | Z54: =_xlfn.RANK.EQ(N54,$N54:$R54, 1) -> 1 | AA54: =_xlfn.RANK.EQ(O54,$N54:$R54, 1) -> 1 | AB54: =_xlfn.RANK.EQ(P54,$N54:$R54, 1) -> 3 | AC54: =_xlfn.RANK.EQ(Q54,$N54:$R54, 1) -> 4 | AD54: =_xlfn.RANK.EQ(R54,$N54:$R54, 1) -> 5
A55: ME354 - 16S | B55: 12 | C55: 0.65 | D55: 3 | E55: 0.15 | F55: 0 | G55: 0 | H55: 0 | I55: 0 | J55: 29 | K55: 0.2 | L55: 0 | M55: =sum(C55+E55+G55+I55+K55+L55) -> 1 | N55: 0 | O55: 0 | P55: 0 | Q55: 9.52 | R55: 90.48 | S55: =SUM(N55:R55) -> 100 | T55: =SUM(N55:O55) -> 0 | U55: =SUM(P55:R55) -> 100 | V55: =SUM(T55:U55) -> 100 | W55: =SUM(N55:O55) -> 0 | X55: =P55 -> 0 | Y55: =SUM(Q55:R55) -> 100 | Z55: =_xlfn.RANK.EQ(N55,$N55:$R55, 1) -> 1 | AA55: =_xlfn.RANK.EQ(O55,$N55:$R55, 1) -> 1 | AB55: =_xlfn.RANK.EQ(P55,$N55:$R55, 1) -> 1 | AC55: =_xlfn.RANK.EQ(Q55,$N55:$R55, 1) -> 4 | AD55: =_xlfn.RANK.EQ(R55,$N55:$R55, 1) -> 5
A56: ME344 - 16S - Chen Sec 18080/18085 | B56: 7 | C56: 0.15 | D56: 0 | E56: 0 | F56: 1 | G56: 0.35 | H56: 0 | I56: 0 | J56: 2 | K56: 0.5 | L56: 0 | M56: =sum(C56+E56+G56+I56+K56+L56) -> 1 | N56: =(0+1)/(15+16+8+10+21+8+1)*100 -> 1.2658228 | O56: =(0+0)/(15+16+8+10+21+8+1)*100 -> 0 | P56: =(8+8)/(15+16+8+10+21+8+1)*100 -> 20.253165 | Q56: =(16+21)/(15+16+8+10+21+8+1)*100 -> 46.835443 | R56: =(15+10)/(15+16+8+10+21+8+1)*100 -> 31.64557 | S56: =SUM(N56:R56) -> 100 | T56: =SUM(N56:O56) -> 1.2658228 | U56: =SUM(P56:R56) -> 98.734177 | V56: =SUM(T56:U56) -> 100 | W56: =SUM(N56:O56) -> 1.2658228 | X56: =P56 -> 20.253165 | Y56: =SUM(Q56:R56) -> 78.481013 | Z56: =_xlfn.RANK.EQ(N56,$N56:$R56, 1) -> 2 | AA56: =_xlfn.RANK.EQ(O56,$N56:$R56, 1) -> 1 | AB56: =_xlfn.RANK.EQ(P56,$N56:$R56, 1) -> 3 | AC56: =_xlfn.RANK.EQ(Q56,$N56:$R56, 1) -> 5 | AD56: =_xlfn.RANK.EQ(R56,$N56:$R56, 1) -> 4
A57: ME344 - 16S - Moon Sec 18075 | B57: 12 | C57: 0.15 | D57: 0 | E57: 0 | F57: 1 | G57: 0.3 | H57: 2 | I57: 0.5 | J57: 0 | K57: 0 | L57: 0.05 | M57: =sum(C57+E57+G57+I57+K57+L57) -> 1 | N57: 0 | O57: =2/(11+3+14+2)*100 -> 6.6666667 | P57: =14/(11+3+14+2)*100 -> 46.666667 | Q57: =3/(11+3+14+2)*100 -> 10 | R57: =11/(11+3+14+2)*100 -> 36.666667 | S57: =SUM(N57:R57) -> 100 | T57: =SUM(N57:O57) -> 6.6666667 | U57: =SUM(P57:R57) -> 93.333333 | V57: =SUM(T57:U57) -> 100 | W57: =SUM(N57:O57) -> 6.6666667 | X57: =P57 -> 46.666667 | Y57: =SUM(Q57:R57) -> 46.666667 | Z57: =_xlfn.RANK.EQ(N57,$N57:$R57, 1) -> 1 | AA57: =_xlfn.RANK.EQ(O57,$N57:$R57, 1) -> 2 | AB57: =_xlfn.RANK.EQ(P57,$N57:$R57, 1) -> 5 | AC57: =_xlfn.RANK.EQ(Q57,$N57:$R57, 1) -> 3 | AD57: =_xlfn.RANK.EQ(R57,$N57:$R57, 1) -> 4
A58: ME330 - 16F | B58: 12 | C58: 0.2 | D58: 0 | E58: 0 | F58: 1 | G58: 0.4 | H58: 2 | I58: 0.4 | J58: 0 | K58: 0 | L58: 0 | M58: =sum(C58+E58+G58+I58+K58+L58) -> 1 | N58: 1.83 | O58: 1.83 | P58: 30.28 | Q58: 38.53 | R58: 27.53 | S58: =SUM(N58:R58) -> 100 | T58: =SUM(N58:O58) -> 3.66 | U58: =SUM(P58:R58) -> 96.34 | V58: =SUM(T58:U58) -> 100 | W58: =SUM(N58:O58) -> 3.66 | X58: =P58 -> 30.28 | Y58: =SUM(Q58:R58) -> 66.06 | Z58: =_xlfn.RANK.EQ(N58,$N58:$R58, 1) -> 1 | AA58: =_xlfn.RANK.EQ(O58,$N58:$R58, 1) -> 1 | AB58: =_xlfn.RANK.EQ(P58,$N58:$R58, 1) -> 4 | AC58: =_xlfn.RANK.EQ(Q58,$N58:$R58, 1) -> 5 | AD58: =_xlfn.RANK.EQ(R58,$N58:$R58, 1) -> 3
A59: ME339 - 16F - Vaibhav Bahadur | B59: 9 | C59: 0.1 | D59: 0 | E59: 0 | F59: 1 | G59: 0.4 | H59: 2 | I59: 0.5 | J59: 0 | K59: 0 | L59: 0 | M59: =sum(C59+E59+G59+I59+K59+L59) -> 1 | N59: 0 | O59: 0 | P59: 8.43 | Q59: 42.17 | R59: 49.4 | S59: =SUM(N59:R59) -> 100 | T59: =SUM(N59:O59) -> 0 | U59: =SUM(P59:R59) -> 100 | V59: =SUM(T59:U59) -> 100 | W59: =SUM(N59:O59) -> 0 | X59: =P59 -> 8.43 | Y59: =SUM(Q59:R59) -> 91.57 | Z59: =_xlfn.RANK.EQ(N59,$N59:$R59, 1) -> 1 | AA59: =_xlfn.RANK.EQ(O59,$N59:$R59, 1) -> 1 | AB59: =_xlfn.RANK.EQ(P59,$N59:$R59, 1) -> 3 | AC59: =_xlfn.RANK.EQ(Q59,$N59:$R59, 1) -> 4 | AD59: =_xlfn.RANK.EQ(R59,$N59:$R59, 1) -> 5
...

Sheet COULD NOT FIND
B1: REASON
A2: Course Code | B2: # HWs | C2: HW Weight
A3: M E-302 | D3: BLUE - UD | E3: ORANGE - UT | F3: RED - UWM
A4: ME353 - Found, but grading scheme very weird
A5: ME354 - could use this one, but it is a lab and has labs (could count them as HWs)
A6: ME386P - 19S Mangolini Sec 18345
A7: some ME330 - did not have number of hw/quiz
A13: ECE/ME 739 -S15- Intro to robotics | B13: 5 | C13: 0.75
A25: UWM & UT LINKS:
A26: https://registrar.wisc.edu/grade-reports/?utm_source=chatgpt.com
A27: https://reports.utexas.edu/spotlight-data/ut-course-grade-distributions

Sheet XDataImport
A1: ='FOUND DATA'!B4 -> # HWs | B1: ='FOUND DATA'!C4 -> HW Weight | C1: ='FOUND DATA'!D4 -> # Project Assignments | D1: ='FOUND DATA'!E4 -> Project Weight | E1: ='FOUND DATA'!F4 -> # Final exam | F1: ='FOUND DATA'!G4 -> Final Weight | G1: ='FOUND DATA'!H4 -> # Other Exams | H1: ='FOUND DATA'!I4 -> Exam Weight | ... K1: ='FOUND DATA'!L4 -> Attend/Misc Weight
A2: ='FOUND DATA'!B5 -> 5 | B2: ='FOUND DATA'!C5 -> 0.2 | C2: ='FOUND DATA'!D5 -> 10 | D2: ='FOUND DATA'!E5 -> 0.6 | E2: ='FOUND DATA'!F5 -> 0 | F2: ='FOUND DATA'!G5 -> 0 | G2: ='FOUND DATA'!H5 -> 0 | H2: ='FOUND DATA'!I5 -> 0 | ... K2: ='FOUND DATA'!L5 -> 0
A3: ='FOUND DATA'!B6 -> 8 | B3: ='FOUND DATA'!C6 -> 0.32 | C3: ='FOUND DATA'!D6 -> 4 | D3: ='FOUND DATA'!E6 -> 0.16 | E3: ='FOUND DATA'!F6 -> 1 | F3: ='FOUND DATA'!G6 -> 0.2 | G3: ='FOUND DATA'!H6 -> 0 | H3: ='FOUND DATA'!I6 -> 0 | ... K3: ='FOUND DATA'!L6 -> 0
A4: ='FOUND DATA'!B7 -> 8 | B4: ='FOUND DATA'!C7 -> 0.32 | C4: ='FOUND DATA'!D7 -> 4 | D4: ='FOUND DATA'!E7 -> 0.16 | E4: ='FOUND DATA'!F7 -> 1 | F4: ='FOUND DATA'!G7 -> 0.2 | G4: ='FOUND DATA'!H7 -> 0 | H4: ='FOUND DATA'!I7 -> 0 | ... K4: ='FOUND DATA'!L7 -> 0
A5: ='FOUND DATA'!B8 -> 8 | B5: ='FOUND DATA'!C8 -> 0.3 | C5: ='FOUND DATA'!D8 -> 6 | D5: ='FOUND DATA'!E8 -> 0.2 | E5: ='FOUND DATA'!F8 -> 0 | F5: ='FOUND DATA'!G8 -> 0 | G5: ='FOUND DATA'!H8 -> 3 | H5: ='FOUND DATA'!I8 -> 0.45 | ... K5: ='FOUND DATA'!L8 -> 0.05
A6: ='FOUND DATA'!B9 -> 16 | B6: ='FOUND DATA'!C9 -> 0.5 | C6: ='FOUND DATA'!D9 -> 6 | D6: ='FOUND DATA'!E9 -> 0.2 | E6: ='FOUND DATA'!F9 -> 0 | F6: ='FOUND DATA'!G9 -> 0 | G6: ='FOUND DATA'!H9 -> 3 | H6: ='FOUND DATA'!I9 -> 0.3 | ... K6: ='FOUND DATA'!L9 -> 0
A7: ='FOUND DATA'!B10 -> 9 | B7: ='FOUND DATA'!C10 -> 0.36 | C7: ='FOUND DATA'!D10 -> 0 | D7: ='FOUND DATA'!E10 -> 0 | E7: ='FOUND DATA'!F10 -> 0 | F7: ='FOUND DATA'!G10 -> 0 | G7: ='FOUND DATA'!H10 -> 4 | H7: ='FOUND DATA'!I10 -> 0.48 | ... K7: ='FOUND DATA'!L10 -> 0
A8: ='FOUND DATA'!B11 -> 11 | B8: ='FOUND DATA'!C11 -> 0.25 | C8: ='FOUND DATA'!D11 -> 5 | D8: ='FOUND DATA'!E11 -> 0.15 | E8: ='FOUND DATA'!F11 -> 1 | F8: ='FOUND DATA'!G11 -> 0.2 | G8: ='FOUND DATA'!H11 -> 3 | H8: ='FOUND DATA'!I11 -> 0.3 | ... K8: ='FOUND DATA'!L11 -> 0.1
A9: ='FOUND DATA'!B12 -> 11 | B9: ='FOUND DATA'!C12 -> 0.25 | C9: ='FOUND DATA'!D12 -> 4 | D9: ='FOUND DATA'!E12 -> 0.15 | E9: ='FOUND DATA'!F12 -> 1 | F9: ='FOUND DATA'!G12 -> 0.2 | G9: ='FOUND DATA'!H12 -> 3 | H9: ='FOUND DATA'!I12 -> 0.3 | ... K9: ='FOUND DATA'!L12 -> 0
A10: ='FOUND DATA'!B13 -> 10 | B10: ='FOUND DATA'!C13 -> 0.25 | C10: ='FOUND DATA'!D13 -> 9 | D10: ='FOUND DATA'!E13 -> 0.15 | E10: ='FOUND DATA'!F13 -> 1 | F10: ='FOUND DATA'!G13 -> 0.2 | G10: ='FOUND DATA'!H13 -> 3 | H10: ='FOUND DATA'!I13 -> 0.3 | ... K10: ='FOUND DATA'!L13 -> 0
A11: ='FOUND DATA'!B14 -> 10 | B11: ='FOUND DATA'!C14 -> 0.25 | C11: ='FOUND DATA'!D14 -> 6 | D11: ='FOUND DATA'!E14 -> 0.15 | E11: ='FOUND DATA'!F14 -> 1 | F11: ='FOUND DATA'!G14 -> 0.2 | G11: ='FOUND DATA'!H14 -> 3 | H11: ='FOUND DATA'!I14 -> 0.3 | ... K11: ='FOUND DATA'!L14 -> 0
A12: ='FOUND DATA'!B15 -> 10 | B12: ='FOUND DATA'!C15 -> 0.25 | C12: ='FOUND DATA'!D15 -> 1 | D12: ='FOUND DATA'!E15 -> 0.1 | E12: ='FOUND DATA'!F15 -> 1 | F12: ='FOUND DATA'!G15 -> 0.2 | G12: ='FOUND DATA'!H15 -> 3 | H12: ='FOUND DATA'!I15 -> 0.3 | ... K12: ='FOUND DATA'!L15 -> 0
... A105: ='FOUND DATA'!B108 -> END | B105: ='FOUND DATA'!C108 -> END | C105: ='FOUND DATA'!D108 -> END | D105: ='FOUND DATA'!E108 -> END | E105: ='FOUND DATA'!F108 -> END | F105: ='FOUND DATA'!G108 -> END | G105: ='FOUND DATA'!H108 -> END | H105: ='FOUND DATA'!I108 -> END | ... K105: ='FOUND DATA'!L108 -> END
A124: ='FOUND DATA'!B126 | B124: ='FOUND DATA'!C126 | C124: ='FOUND DATA'!D126 | D124: ='FOUND DATA'!E126 | E124: ='FOUND DATA'!F126 | F124: ='FOUND DATA'!G126 | G124: ='FOUND DATA'!H126 | H124: ='FOUND DATA'!I126 | ... K124: ='FOUND DATA'!L126
A125: ='FOUND DATA'!B127 | B125: ='FOUND DATA'!C127 | C125: ='FOUND DATA'!D127 | D125: ='FOUND DATA'!E127 | E125: ='FOUND DATA'!F127 | F125: ='FOUND DATA'!G127 | G125: ='FOUND DATA'!H127 | H125: ='FOUND DATA'!I127 | ... K125: ='FOUND DATA'!L127
A126: ='FOUND DATA'!B128 | B126: ='FOUND DATA'!C128 | C126: ='FOUND DATA'!D128 | D126: ='FOUND DATA'!E128 | E126: ='FOUND DATA'!F128 | F126: ='FOUND DATA'!G128 | G126: ='FOUND DATA'!H128 | H126: ='FOUND DATA'!I128 | ... K126: ='FOUND DATA'!L128
A127: ='FOUND DATA'!B129 | B127: ='FOUND DATA'!C129 | C127: ='FOUND DATA'!D129 | D127: ='FOUND DATA'!E129 | E127: ='FOUND DATA'!F129 | F127: ='FOUND DATA'!G129 | G127: ='FOUND DATA'!H129 | H127: ='FOUND DATA'!I129 | ... K127: ='FOUND DATA'!L129
A128: ='FOUND DATA'!B130 | B128: ='FOUND DATA'!C130 | C128: ='FOUND DATA'!D130 | D128: ='FOUND DATA'!E130 | E128: ='FOUND DATA'!F130 | F128: ='FOUND DATA'!G130 | G128: ='FOUND DATA'!H130 | H128: ='FOUND DATA'!I130 | ... K128: ='FOUND DATA'!L130
A129: ='FOUND DATA'!B111 | B129: ='FOUND DATA'!C111 | C129: ='FOUND DATA'!D111 | D129: ='FOUND DATA'!E111 | E129: ='FOUND DATA'!F111 | F129: ='FOUND DATA'!G111 | G129: ='FOUND DATA'!H111 | H129: ='FOUND DATA'!I111 | ... K129: ='FOUND DATA'!L111
A130: ='FOUND DATA'!B112 | B130: ='FOUND DATA'!C112 | C130: ='FOUND DATA'!D112 | D130: ='FOUND DATA'!E112 | E130: ='FOUND DATA'!F112 | F130: ='FOUND DATA'!G112 | G130: ='FOUND DATA'!H112 | H130: ='FOUND DATA'!I112 | ... K130: ='FOUND DATA'!L112
A131: ='FOUND DATA'!B113 | B131: ='FOUND DATA'!C113 | C131: ='FOUND DATA'!D113 | D131: ='FOUND DATA'!E113 | E131: ='FOUND DATA'!F113 | F131: ='FOUND DATA'!G113 | G131: ='FOUND DATA'!H113 | H131: ='FOUND DATA'!I113 | ... K131: ='FOUND DATA'!L113
A132: ='FOUND DATA'!B114 | B132: ='FOUND DATA'!C114 | C132: ='FOUND DATA'!D114 | D132: ='FOUND DATA'!E114 | E132: ='FOUND DATA'!F114 | F132: ='FOUND DATA'!G114 | G132: ='FOUND DATA'!H114 | H132: ='FOUND DATA'!I114 | ... K132: ='FOUND DATA'!L114
A146: ='FOUND DATA'!B124 | B146: ='FOUND DATA'!C124 | C146: ='FOUND DATA'!D124 | D146: ='FOUND DATA'!E124 | E146: ='FOUND DATA'!F124 | F146: ='FOUND DATA'!G124 | G146: ='FOUND DATA'!H124 | H146: ='FOUND DATA'!I124 | ... K146: ='FOUND DATA'!L124
A147: ='FOUND DATA'!B125 | B147: ='FOUND DATA'!C125 | C147: ='FOUND DATA'!D125 | D147: ='FOUND DATA'!E125 | E147: ='FOUND DATA'!F125 | F147: ='FOUND DATA'!G125 | G147: ='FOUND DATA'!H125 | H147: ='FOUND DATA'!I125 | ... K147: ='FOUND DATA'!L125
A148: ='FOUND DATA'!B126 | B148: ='FOUND DATA'!C126 | C148: ='FOUND DATA'!D126 | D148: ='FOUND DATA'!E126 | E148: ='FOUND DATA'!F126 | F148: ='FOUND DATA'!G126 | G148: ='FOUND DATA'!H126 | H148: ='FOUND DATA'!I126 | ... K148: ='FOUND DATA'!L126
A149: ='FOUND DATA'!B127 | B149: ='FOUND DATA'!C127 | C149: ='FOUND DATA'!D127 | D149: ='FOUND DATA'!E127 | E149: ='FOUND DATA'!F127 | F149: ='FOUND DATA'!G127 | G149: ='FOUND DATA'!H127 | H149: ='FOUND DATA'!I127 | ... K149: ='FOUND DATA'!L127
A150: ='FOUND DATA'!B128 | B150: ='FOUND DATA'!C128 | C150: ='FOUND DATA'!D128 | D150: ='FOUND DATA'!E128 | E150: ='FOUND DATA'!F128 | F150: ='FOUND DATA'!G128 | G150: ='FOUND DATA'!H128 | H150: ='FOUND DATA'!I128 | ... K150: ='FOUND DATA'!L128
A151: ='FOUND DATA'!B129 | B151: ='FOUND DATA'!C129 | C151: ='FOUND DATA'!D129 | D151: ='FOUND DATA'!E129 | E151: ='FOUND DATA'!F129 | F151: ='FOUND DATA'!G129 | G151: ='FOUND DATA'!H129 | H151: ='FOUND DATA'!I129 | ... K151: ='FOUND DATA'!L129
A152: ='FOUND DATA'!B130 | B152: ='FOUND DATA'!C130 | C152: ='FOUND DATA'!D130 | D152: ='FOUND DATA'!E130 | E152: ='FOUND DATA'!F130 | F152: ='FOUND DATA'!G130 | G152: ='FOUND DATA'!H130 | H152: ='FOUND DATA'!I130 | ... K152: ='FOUND DATA'!L130
A153: ='FOUND DATA'!B131 | B153: ='FOUND DATA'!C131 | C153: ='FOUND DATA'!D131 | D153: ='FOUND DATA'!E131 | E153: ='FOUND DATA'!F131 | F153: ='FOUND DATA'!G131 | G153: ='FOUND DATA'!H131 | H153: ='FOUND DATA'!I131 | ... K153: ='FOUND DATA'!L131
A154: ='FOUND DATA'!B132 | B154: ='FOUND DATA'!C132 | C154: ='FOUND DATA'!D132 | D154: ='FOUND DATA'!E132 | E154: ='FOUND DATA'!F132 | F154: ='FOUND DATA'!G132 | G154: ='FOUND DATA'!H132 | H154: ='FOUND DATA'!I132 | ... K154: ='FOUND DATA'!L132
A155: ='FOUND DATA'!B133 | B155: ='FOUND DATA'!C133 | C155: ='FOUND DATA'!D133 | D155: ='FOUND DATA'!E133 | E155: ='FOUND DATA'!F133 | F155: ='FOUND DATA'!G133 | G155: ='FOUND DATA'!H133 | H155: ='FOUND DATA'!I133 | ... K155: ='FOUND DATA'!L133
A156: ='FOUND DATA'!B134 | B156: ='FOUND DATA'!C134 | C156: ='FOUND DATA'!D134 | D156: ='FOUND DATA'!E134 | E156: ='FOUND DATA'!F134 | F156: ='FOUND DATA'!G134 | G156: ='FOUND DATA'!H134 | H156: ='FOUND DATA'!I134 | ... K156: ='FOUND DATA'!L134
A157: ='FOUND DATA'!B135 | B157: ='FOUND DATA'!C135 | C157: ='FOUND DATA'!D135 | D157: ='FOUND DATA'!E135 | E157: ='FOUND DATA'!F135 | F157: ='FOUND DATA'!G135 | G157: ='FOUND DATA'!H135 | H157: ='FOUND DATA'!I135 | ... K157: ='FOUND DATA'!L135
... A185: ='FOUND DATA'!B163 | B185: ='FOUND DATA'!C163 | C185: ='FOUND DATA'!D163 | D185: ='FOUND DATA'!E163 | E185: ='FOUND DATA'!F163 | F185: ='FOUND DATA'!G163 | G185: ='FOUND DATA'!H163 | H185: ='FOUND DATA'!I163 | ... K185: ='FOUND DATA'!L163

Sheet XDataImport - EXAMS & HW ONLY
A1: ='FOUND DATA'!B4 -> # HWs | B1: ='FOUND DATA'!C4 -> HW Weight | C1: ='FOUND DATA'!D4 -> # Project Assignments | D1: ='FOUND DATA'!E4 -> Project Weight | E1: ='FOUND DATA'!F4 -> # Final exam | F1: ='FOUND DATA'!G4 -> Final Weight
A2: ='FOUND DATA'!B5 -> 5 | B2: ='FOUND DATA'!C5 -> 0.2 | C2: ='FOUND DATA'!D5 -> 10 | D2: ='FOUND DATA'!E5 -> 0.6 | E2: ='FOUND DATA'!F5 -> 0 | F2: ='FOUND DATA'!G5 -> 0
A3: ='FOUND DATA'!B6 -> 8 | B3: ='FOUND DATA'!C6 -> 0.32 | C3: ='FOUND DATA'!D6 -> 4 | D3: ='FOUND DATA'!E6 -> 0.16 | E3: ='FOUND DATA'!F6 -> 1 | F3: ='FOUND DATA'!G6 -> 0.2
A4: ='FOUND DATA'!B7 -> 8 | B4: ='FOUND DATA'!C7 -> 0.32 | C4: ='FOUND DATA'!D7 -> 4 | D4: ='FOUND DATA'!E7 -> 0.16 | E4: ='FOUND DATA'!F7 -> 1 | F4: ='FOUND DATA'!G7 -> 0.2
A5: ='FOUND DATA'!B8 -> 8 | B5: ='FOUND DATA'!C8 -> 0.3 | C5: ='FOUND DATA'!D8 -> 6 | D5: ='FOUND DATA'!E8 -> 0.2 | E5: ='FOUND DATA'!F8 -> 0 | F5: ='FOUND DATA'!G8 -> 0
A6: ='FOUND DATA'!B9 -> 16 | B6: ='FOUND DATA'!C9 -> 0.5 | C6: ='FOUND DATA'!D9 -> 6 | D6: ='FOUND DATA'!E9 -> 0.2 | E6: ='FOUND DATA'!F9 -> 0 | F6: ='FOUND DATA'!G9 -> 0
A7: ='FOUND DATA'!B10 -> 9 | B7: ='FOUND DATA'!C10 -> 0.36 | C7: ='FOUND DATA'!D10 -> 0 | D7: ='FOUND DATA'!E10 -> 0 | E7: ='FOUND DATA'!F10 -> 0 | F7: ='FOUND DATA'!G10 -> 0
A8: ='FOUND DATA'!B11 -> 11 | B8: ='FOUND DATA'!C11 -> 0.25 | C8: ='FOUND DATA'!D11 -> 5 | D8: ='FOUND DATA'!E11 -> 0.15 | E8: ='FOUND DATA'!F11 -> 1 | F8: ='FOUND DATA'!G11 -> 0.2
A9: ='FOUND DATA'!B12 -> 11 | B9: ='FOUND DATA'!C12 -> 0.25 | C9: ='FOUND DATA'!D12 -> 4 | D9: ='FOUND DATA'!E12 -> 0.15 | E9: ='FOUND DATA'!F12 -> 1 | F9: ='FOUND DATA'!G12 -> 0.2
A10: ='FOUND DATA'!B13 -> 10 | B10: ='FOUND DATA'!C13 -> 0.25 | C10: ='FOUND DATA'!D13 -> 9 | D10: ='FOUND DATA'!E13 -> 0.15 | E10: ='FOUND DATA'!F13 -> 1 | F10: ='FOUND DATA'!G13 -> 0.2
A11: ='FOUND DATA'!B14 -> 10 | B11: ='FOUND DATA'!C14 -> 0.25 | C11: ='FOUND DATA'!D14 -> 6 | D11: ='FOUND DATA'!E14 -> 0.15 | E11: ='FOUND DATA'!F14 -> 1 | F11: ='FOUND DATA'!G14 -> 0.2
A12: ='FOUND DATA'!B15 -> 10 | B12: ='FOUND DATA'!C15 -> 0.25 | C12: ='FOUND DATA'!D15 -> 1 | D12: ='FOUND DATA'!E15 -> 0.1 | E12: ='FOUND DATA'!F15 -> 1 | F12: ='FOUND DATA'!G15 -> 0.2
... A106: ='FOUND DATA'!B109 | B106: ='FOUND DATA'!C109 | C106: ='FOUND DATA'!D109 | D106: ='FOUND DATA'!E109 | E106: ='FOUND DATA'!F109 | F106: ='FOUND DATA'!G109
A124: ='FOUND DATA'!B126 | B124: ='FOUND DATA'!C126 | C124: ='FOUND DATA'!F126 | D124: ='FOUND DATA'!G126 | E124: ='FOUND DATA'!H126 | F124: ='FOUND DATA'!I126
A125: ='FOUND DATA'!B127 | B125: ='FOUND DATA'!C127 | C125: ='FOUND DATA'!F127 | D125: ='FOUND DATA'!G127 | E125: ='FOUND DATA'!H127 | F125: ='FOUND DATA'!I127
A126: ='FOUND DATA'!B128 | B126: ='FOUND DATA'!C128 | C126: ='FOUND DATA'!F128 | D126: ='FOUND DATA'!G128 | E126: ='FOUND DATA'!H128 | F126: ='FOUND DATA'!I128
A127: ='FOUND DATA'!B129 | B127: ='FOUND DATA'!C129 | C127: ='FOUND DATA'!F129 | D127: ='FOUND DATA'!G129 | E127: ='FOUND DATA'!H129 | F127: ='FOUND DATA'!I129
A128: ='FOUND DATA'!B130 | B128: ='FOUND DATA'!C130 | C128: ='FOUND DATA'!F130 | D128: ='FOUND DATA'!G130 | E128: ='FOUND DATA'!H130 | F128: ='FOUND DATA'!I130
A129: ='FOUND DATA'!B111 | B129: ='FOUND DATA'!C111 | C129: ='FOUND DATA'!F111 | D129: ='FOUND DATA'!G111 | E129: ='FOUND DATA'!H111 | F129: ='FOUND DATA'!I111
A130: ='FOUND DATA'!B112 | B130: ='FOUND DATA'!C112 | C130: ='FOUND DATA'!F112 | D130: ='FOUND DATA'!G112 | E130: ='FOUND DATA'!H112 | F130: ='FOUND DATA'!I112
A131: ='FOUND DATA'!B113 | B131: ='FOUND DATA'!C113 | C131: ='FOUND DATA'!F113 | D131: ='FOUND DATA'!G113 | E131: ='FOUND DATA'!H113 | F131: ='FOUND DATA'!I113
A132: ='FOUND DATA'!B114 | B132: ='FOUND DATA'!C114 | C132: ='FOUND DATA'!F114 | D132: ='FOUND DATA'!G114 | E132: ='FOUND DATA'!H114 | F132: ='FOUND DATA'!I114
A146: ='FOUND DATA'!B124 | B146: ='FOUND DATA'!C124 | C146: ='FOUND DATA'!F124 | D146: ='FOUND DATA'!G124 | E146: ='FOUND DATA'!H124 | F146: ='FOUND DATA'!I124
A147: ='FOUND DATA'!B125 | B147: ='FOUND DATA'!C125 | C147: ='FOUND DATA'!F125 | D147: ='FOUND DATA'!G125 | E147: ='FOUND DATA'!H125 | F147: ='FOUND DATA'!I125
A148: ='FOUND DATA'!B126 | B148: ='FOUND DATA'!C126 | C148: ='FOUND DATA'!F126 | D148: ='FOUND DATA'!G126 | E148: ='FOUND DATA'!H126 | F148: ='FOUND DATA'!I126
A149: ='FOUND DATA'!B127 | B149: ='FOUND DATA'!C127 | C149: ='FOUND DATA'!F127 | D149: ='FOUND DATA'!G127 | E149: ='FOUND DATA'!H127 | F149: ='FOUND DATA'!I127
A150: ='FOUND DATA'!B128 | B150: ='FOUND DATA'!C128 | C150: ='FOUND DATA'!F128 | D150: ='FOUND DATA'!G128 | E150: ='FOUND DATA'!H128 | F150: ='FOUND DATA'!I128
A151: ='FOUND DATA'!B129 | B151: ='FOUND DATA'!C129 | C151: ='FOUND DATA'!F129 | D151: ='FOUND DATA'!G129 | E151: ='FOUND DATA'!H129 | F151: ='FOUND DATA'!I129
A152: ='FOUND DATA'!B130 | B152: ='FOUND DATA'!C130 | C152: ='FOUND DATA'!F130 | D152: ='FOUND DATA'!G130 | E152: ='FOUND DATA'!H130 | F152: ='FOUND DATA'!I130
A153: ='FOUND DATA'!B131 | B153: ='FOUND DATA'!C131 | C153: ='FOUND DATA'!F131 | D153: ='FOUND DATA'!G131 | E153: ='FOUND DATA'!H131 | F153: ='FOUND DATA'!I131
A154: ='FOUND DATA'!B132 | B154: ='FOUND DATA'!C132 | C154: ='FOUND DATA'!F132 | D154: ='FOUND DATA'!G132 | E154: ='FOUND DATA'!H132 | F154: ='FOUND DATA'!I132
A155: ='FOUND DATA'!B133 | B155: ='FOUND DATA'!C133 | C155: ='FOUND DATA'!F133 | D155: ='FOUND DATA'!G133 | E155: ='FOUND DATA'!H133 | F155: ='FOUND DATA'!I133
A156: ='FOUND DATA'!B134 | B156: ='FOUND DATA'!C134 | C156: ='FOUND DATA'!F134 | D156: ='FOUND DATA'!G134 | E156: ='FOUND DATA'!H134 | F156: ='FOUND DATA'!I134
A157: ='FOUND DATA'!B135 | B157: ='FOUND DATA'!C135 | C157: ='FOUND DATA'!F135 | D157: ='FOUND DATA'!G135 | E157: ='FOUND DATA'!H135 | F157: ='FOUND DATA'!I135
... A185: ='FOUND DATA'!B163 | B185: ='FOUND DATA'!C163 | C185: ='FOUND DATA'!F163 | D185: ='FOUND DATA'!G163 | E185: ='FOUND DATA'!H163 | F185: ='FOUND DATA'!I163

Sheet XDataImport - EXAMS (COMBINED) 
A1: ='FOUND DATA'!B4 -> # HWs | B1: ='FOUND DATA'!C4 -> HW Weight | C1: ='FOUND DATA'!D4 -> # Project Assignments | D1: ='FOUND DATA'!E4 -> Project Weight
A2: ='FOUND DATA'!B5 -> 5 | B2: ='FOUND DATA'!C5 -> 0.2 | C2: ='FOUND DATA'!D5 -> 10 | D2: ='FOUND DATA'!E5 -> 0.6
A3: ='FOUND DATA'!B6 -> 8 | B3: ='FOUND DATA'!C6 -> 0.32 | C3: ='FOUND DATA'!D6 -> 4 | D3: ='FOUND DATA'!E6 -> 0.16
A4: ='FOUND DATA'!B7 -> 8 | B4: ='FOUND DATA'!C7 -> 0.32 | C4: ='FOUND DATA'!D7 -> 4 | D4: ='FOUND DATA'!E7 -> 0.16
A5: ='FOUND DATA'!B8 -> 8 | B5: ='FOUND DATA'!C8 -> 0.3 | C5: ='FOUND DATA'!D8 -> 6 | D5: ='FOUND DATA'!E8 -> 0.2
A6: ='FOUND DATA'!B9 -> 16 | B6: ='FOUND DATA'!C9 -> 0.5 | C6: ='FOUND DATA'!D9 -> 6 | D6: ='FOUND DATA'!E9 -> 0.2
A7: ='FOUND DATA'!B10 -> 9 | B7: ='FOUND DATA'!C10 -> 0.36 | C7: ='FOUND DATA'!D10 -> 0 | D7: ='FOUND DATA'!E10 -> 0
A8: ='FOUND DATA'!B11 -> 11 | B8: ='FOUND DATA'!C11 -> 0.25 | C8: ='FOUND DATA'!D11 -> 5 | D8: ='FOUND DATA'!E11 -> 0.15
A9: ='FOUND DATA'!B12 -> 11 | B9: ='FOUND DATA'!C12 -> 0.25 | C9: ='FOUND DATA'!D12 -> 4 | D9: ='FOUND DATA'!E12 -> 0.15
A10: ='FOUND DATA'!B13 -> 10 | B10: ='FOUND DATA'!C13 -> 0.25 | C10: ='FOUND DATA'!D13 -> 9 | D10: ='FOUND DATA'!E13 -> 0.15
A11: ='FOUND DATA'!B14 -> 10 | B11: ='FOUND DATA'!C14 -> 0.25 | C11: ='FOUND DATA'!D14 -> 6 | D11: ='FOUND DATA'!E14 -> 0.15
A12: ='FOUND DATA'!B15 -> 10 | B12: ='FOUND DATA'!C15 -> 0.25 | C12: ='FOUND DATA'!D15 -> 1 | D12: ='FOUND DATA'!E15 -> 0.1
... A105: ='FOUND DATA'!B108 -> END | B105: ='FOUND DATA'!C108 -> END | C105: ='FOUND DATA'!D108 -> END | D105: ='FOUND DATA'!E108 -> END
A124: ='FOUND DATA'!B126 | B124: ='FOUND DATA'!C126
A125: ='FOUND DATA'!B127 | B125: ='FOUND DATA'!C127
A126: ='FOUND DATA'!B128 | B126: ='FOUND DATA'!C128
A127: ='FOUND DATA'!B129 | B127: ='FOUND DATA'!C129
A128: ='FOUND DATA'!B130 | B128: ='FOUND DATA'!C130
A129: ='FOUND DATA'!B111 | B129: ='FOUND DATA'!C111
A130: ='FOUND DATA'!B112 | B130: ='FOUND DATA'!C112
A131: ='FOUND DATA'!B113 | B131: ='FOUND DATA'!C113
A132: ='FOUND DATA'!B114 | B132: ='FOUND DATA'!C114
A146: ='FOUND DATA'!B124 | B146: ='FOUND DATA'!C124
A147: ='FOUND DATA'!B125 | B147: ='FOUND DATA'!C125
A148: ='FOUND DATA'!B126 | B148: ='FOUND DATA'!C126
A149: ='FOUND DATA'!B127 | B149: ='FOUND DATA'!C127
A150: ='FOUND DATA'!B128 | B150: ='FOUND DATA'!C128
A151: ='FOUND DATA'!B129 | B151: ='FOUND DATA'!C129
A152: ='FOUND DATA'!B130 | B152: ='FOUND DATA'!C130
A153: ='FOUND DATA'!B131 | B153: ='FOUND DATA'!C131
A154: ='FOUND DATA'!B132 | B154: ='FOUND DATA'!C132
A155: ='FOUND DATA'!B133 | B155: ='FOUND DATA'!C133
A156: ='FOUND DATA'!B134 | B156: ='FOUND DATA'!C134
A157: ='FOUND DATA'!B135 | B157: ='FOUND DATA'!C135
... A185: ='FOUND DATA'!B163 | B185: ='FOUND DATA'!C163

Sheet XDataImport - NO QUIZ OR MISC
A1: ='FOUND DATA'!B4 -> # HWs | B1: ='FOUND DATA'!C4 -> HW Weight | C1: ='FOUND DATA'!D4 -> # Project Assignments | D1: ='FOUND DATA'!E4 -> Project Weight | E1: ='FOUND DATA'!F4 -> # Final exam | F1: ='FOUND DATA'!G4 -> Final Weight | G1: ='FOUND DATA'!H4 -> # Other Exams | H1: ='FOUND DATA'!I4 -> Exam Weight
A2: ='FOUND DATA'!B5 -> 5 | B2: ='FOUND DATA'!C5 -> 0.2 | C2: ='FOUND DATA'!D5 -> 10 | D2: ='FOUND DATA'!E5 -> 0.6 | E2: ='FOUND DATA'!F5 -> 0 | F2: ='FOUND DATA'!G5 -> 0 | G2: ='FOUND DATA'!H5 -> 0 | H2: ='FOUND DATA'!I5 -> 0
A3: ='FOUND DATA'!B6 -> 8 | B3: ='FOUND DATA'!C6 -> 0.32 | C3: ='FOUND DATA'!D6 -> 4 | D3: ='FOUND DATA'!E6 -> 0.16 | E3: ='FOUND DATA'!F6 -> 1 | F3: ='FOUND DATA'!G6 -> 0.2 | G3: ='FOUND DATA'!H6 -> 0 | H3: ='FOUND DATA'!I6 -> 0
A4: ='FOUND DATA'!B7 -> 8 | B4: ='FOUND DATA'!C7 -> 0.32 | C4: ='FOUND DATA'!D7 -> 4 | D4: ='FOUND DATA'!E7 -> 0.16 | E4: ='FOUND DATA'!F7 -> 1 | F4: ='FOUND DATA'!G7 -> 0.2 | G4: ='FOUND DATA'!H7 -> 0 | H4: ='FOUND DATA'!I7 -> 0
A5: ='FOUND DATA'!B8 -> 8 | B5: ='FOUND DATA'!C8 -> 0.3 | C5: ='FOUND DATA'!D8 -> 6 | D5: ='FOUND DATA'!E8 -> 0.2 | E5: ='FOUND DATA'!F8 -> 0 | F5: ='FOUND DATA'!G8 -> 0 | G5: ='FOUND DATA'!H8 -> 3 | H5: ='FOUND DATA'!I8 -> 0.45
A6: ='FOUND DATA'!B9 -> 16 | B6: ='FOUND DATA'!C9 -> 0.5 | C6: ='FOUND DATA'!D9 -> 6 | D6: ='FOUND DATA'!E9 -> 0.2 | E6: ='FOUND DATA'!F9 -> 0 | F6: ='FOUND DATA'!G9 -> 0 | G6: ='FOUND DATA'!H9 -> 3 | H6: ='FOUND DATA'!I9 -> 0.3
A7: ='FOUND DATA'!B10 -> 9 | B7: ='FOUND DATA'!C10 -> 0.36 | C7: ='FOUND DATA'!D10 -> 0 | D7: ='FOUND DATA'!E10 -> 0 | E7: ='FOUND DATA'!F10 -> 0 | F7: ='FOUND DATA'!G10 -> 0 | G7: ='FOUND DATA'!H10 -> 4 | H7: ='FOUND DATA'!I10 -> 0.48
A8: ='FOUND DATA'!B11 -> 11 | B8: ='FOUND DATA'!C11 -> 0.25 | C8: ='FOUND DATA'!D11 -> 5 | D8: ='FOUND DATA'!E11 -> 0.15 | E8: ='FOUND DATA'!F11 -> 1 | F8: ='FOUND DATA'!G11 -> 0.2 | G8: ='FOUND DATA'!H11 -> 3 | H8: ='FOUND DATA'!I11 -> 0.3
A9: ='FOUND DATA'!B12 -> 11 | B9: ='FOUND DATA'!C12 -> 0.25 | C9: ='FOUND DATA'!D12 -> 4 | D9: ='FOUND DATA'!E12 -> 0.15 | E9: ='FOUND DATA'!F12 -> 1 | F9: ='FOUND DATA'!G12 -> 0.2 | G9: ='FOUND DATA'!H12 -> 3 | H9: ='FOUND DATA'!I12 -> 0.3
A10: ='FOUND DATA'!B13 -> 10 | B10: ='FOUND DATA'!C13 -> 0.25 | C10: ='FOUND DATA'!D13 -> 9 | D10: ='FOUND DATA'!E13 -> 0.15 | E10: ='FOUND DATA'!F13 -> 1 | F10: ='FOUND DATA'!G13 -> 0.2 | G10: ='FOUND DATA'!H13 -> 3 | H10: ='FOUND DATA'!I13 -> 0.3
A11: ='FOUND DATA'!B14 -> 10 | B11: ='FOUND DATA'!C14 -> 0.25 | C11: ='FOUND DATA'!D14 -> 6 | D11: ='FOUND DATA'!E14 -> 0.15 | E11: ='FOUND DATA'!F14 -> 1 | F11: ='FOUND DATA'!G14 -> 0.2 | G11: ='FOUND DATA'!H14 -> 3 | H11: ='FOUND DATA'!I14 -> 0.3
A12: ='FOUND DATA'!B15 -> 10 | B12: ='FOUND DATA'!C15 -> 0.25 | C12: ='FOUND DATA'!D15 -> 1 | D12: ='FOUND DATA'!E15 -> 0.1 | E12: ='FOUND DATA'!F15 -> 1 | F12: ='FOUND DATA'!G15 -> 0.2 | G12: ='FOUND DATA'!H15 -> 3 | H12: ='FOUND DATA'!I15 -> 0.3
... A105: ='FOUND DATA'!B108 -> END | B105: ='FOUND DATA'!C108 -> END | C105: ='FOUND DATA'!D108 -> END | D105: ='FOUND DATA'!E108 -> END | E105: ='FOUND DATA'!F108 -> END | F105: ='FOUND DATA'!G108 -> END | G105: ='FOUND DATA'!H108 -> END | H105: ='FOUND DATA'!I108 -> END
A124: ='FOUND DATA'!B126 | B124: ='FOUND DATA'!C126 | C124: ='FOUND DATA'!D126 | D124: ='FOUND DATA'!E126 | E124: ='FOUND DATA'!F126 | F124: ='FOUND DATA'!G126 | G124: ='FOUND DATA'!H126 | H124: ='FOUND DATA'!I126
A125: ='FOUND DATA'!B127 | B125: ='FOUND DATA'!C127 | C125: ='FOUND DATA'!D127 | D125: ='FOUND DATA'!E127 | E125: ='FOUND DATA'!F127 | F125: ='FOUND DATA'!G127 | G125: ='FOUND DATA'!H127 | H125: ='FOUND DATA'!I127
A126: ='FOUND DATA'!B128 | B126: ='FOUND DATA'!C128 | C126: ='FOUND DATA'!D128 | D126: ='FOUND DATA'!E128 | E126: ='FOUND DATA'!F128 | F126: ='FOUND DATA'!G128 | G126: ='FOUND DATA'!H128 | H126: ='FOUND DATA'!I128
A127: ='FOUND DATA'!B129 | B127: ='FOUND DATA'!C129 | C127: ='FOUND DATA'!D129 | D127: ='FOUND DATA'!E129 | E127: ='FOUND DATA'!F129 | F127: ='FOUND DATA'!G129 | G127: ='FOUND DATA'!H129 | H127: ='FOUND DATA'!I129
A128: ='FOUND DATA'!B130 | B128: ='FOUND DATA'!C130 | C128: ='FOUND DATA'!D130 | D128: ='FOUND DATA'!E130 | E128: ='FOUND DATA'!F130 | F128: ='FOUND DATA'!G130 | G128: ='FOUND DATA'!H130 | H128: ='FOUND DATA'!I130
A129: ='FOUND DATA'!B111 | B129: ='FOUND DATA'!C111 | C129: ='FOUND DATA'!D111 | D129: ='FOUND DATA'!E111 | E129: ='FOUND DATA'!F111 | F129: ='FOUND DATA'!G111 | G129: ='FOUND DATA'!H111 | H129: ='FOUND DATA'!I111
A130: ='FOUND DATA'!B112 | B130: ='FOUND DATA'!C112 | C130: ='FOUND DATA'!D112 | D130: ='FOUND DATA'!E112 | E130: ='FOUND DATA'!F112 | F130: ='FOUND DATA'!G112 | G130: ='FOUND DATA'!H112 | H130: ='FOUND DATA'!I112
A131: ='FOUND DATA'!B113 | B131: ='FOUND DATA'!C113 | C131: ='FOUND DATA'!D113 | D131: ='FOUND DATA'!E113 | E131: ='FOUND DATA'!F113 | F131: ='FOUND DATA'!G113 | G131: ='FOUND DATA'!H113 | H131: ='FOUND DATA'!I113
A132: ='FOUND DATA'!B114 | B132: ='FOUND DATA'!C114 | C132: ='FOUND DATA'!D114 | D132: ='FOUND DATA'!E114 | E132: ='FOUND DATA'!F114 | F132: ='FOUND DATA'!G114 | G132: ='FOUND DATA'!H114 | H132: ='FOUND DATA'!I114
A146: ='FOUND DATA'!B124 | B146: ='FOUND DATA'!C124 | C146: ='FOUND DATA'!D124 | D146: ='FOUND DATA'!E124 | E146: ='FOUND DATA'!F124 | F146: ='FOUND DATA'!G124 | G146: ='FOUND DATA'!H124 | H146: ='FOUND DATA'!I124
A147: ='FOUND DATA'!B125 | B147: ='FOUND DATA'!C125 | C147: ='FOUND DATA'!D125 | D147: ='FOUND DATA'!E125 | E147: ='FOUND DATA'!F125 | F147: ='FOUND DATA'!G125 | G147: ='FOUND DATA'!H125 | H147: ='FOUND DATA'!I125
A148: ='FOUND DATA'!B126 | B148: ='FOUND DATA'!C126 | C148: ='FOUND DATA'!D126 | D148: ='FOUND DATA'!E126 | E148: ='FOUND DATA'!F126 | F148: ='FOUND DATA'!G126 | G148: ='FOUND DATA'!H126 | H148: ='FOUND DATA'!I126
A149: ='FOUND DATA'!B127 | B149: ='FOUND DATA'!C127 | C149: ='FOUND DATA'!D127 | D149: ='FOUND DATA'!E127 | E149: ='FOUND DATA'!F127 | F149: ='FOUND DATA'!G127 | G149: ='FOUND DATA'!H127 | H149: ='FOUND DATA'!I127
A150: ='FOUND DATA'!B128 | B150: ='FOUND DATA'!C128 | C150: ='FOUND DATA'!D128 | D150: ='FOUND DATA'!E128 | E150: ='FOUND DATA'!F128 | F150: ='FOUND DATA'!G128 | G150: ='FOUND DATA'!H128 | H150: ='FOUND DATA'!I128
A151: ='FOUND DATA'!B129 | B151: ='FOUND DATA'!C129 | C151: ='FOUND DATA'!D129 | D151: ='FOUND DATA'!E129 | E151: ='FOUND DATA'!F129 | F151: ='FOUND DATA'!G129 | G151: ='FOUND DATA'!H129 | H151: ='FOUND DATA'!I129
A152: ='FOUND DATA'!B130 | B152: ='FOUND DATA'!C130 | C152: ='FOUND DATA'!D130 | D152: ='FOUND DATA'!E130 | E152: ='FOUND DATA'!F130 | F152: ='FOUND DATA'!G130 | G152: ='FOUND DATA'!H130 | H152: ='FOUND DATA'!I130
A153: ='FOUND DATA'!B131 | B153: ='FOUND DATA'!C131 | C153: ='FOUND DATA'!D131 | D153: ='FOUND DATA'!E131 | E153: ='FOUND DATA'!F131 | F153: ='FOUND DATA'!G131 | G153: ='FOUND DATA'!H131 | H153: ='FOUND DATA'!I131
A154: ='FOUND DATA'!B132 | B154: ='FOUND DATA'!C132 | C154: ='FOUND DATA'!D132 | D154: ='FOUND DATA'!E132 | E154: ='FOUND DATA'!F132 | F154: ='FOUND DATA'!G132 | G154: ='FOUND DATA'!H132 | H154: ='FOUND DATA'!I132
A155: ='FOUND DATA'!B133 | B155: ='FOUND DATA'!C133 | C155: ='FOUND DATA'!D133 | D155: ='FOUND DATA'!E133 | E155: ='FOUND DATA'!F133 | F155: ='FOUND DATA'!G133 | G155: ='FOUND DATA'!H133 | H155: ='FOUND DATA'!I133
A156: ='FOUND DATA'!B134 | B156: ='FOUND DATA'!C134 | C156: ='FOUND DATA'!D134 | D156: ='FOUND DATA'!E134 | E156: ='FOUND DATA'!F134 | F156: ='FOUND DATA'!G134 | G156: ='FOUND DATA'!H134 | H156: ='FOUND DATA'!I134
A157: ='FOUND DATA'!B135 | B157: ='FOUND DATA'!C135 | C157: ='FOUND DATA'!D135 | D157: ='FOUND DATA'!E135 | E157: ='FOUND DATA'!F135 | F157: ='FOUND DATA'!G135 | G157: ='FOUND DATA'!H135 | H157: ='FOUND DATA'!I135
... A185: ='FOUND DATA'!B163 | B185: ='FOUND DATA'!C163 | C185: ='FOUND DATA'!D163 | D185: ='FOUND DATA'!E163 | E185: ='FOUND DATA'!F163 | F185: ='FOUND DATA'!G163 | G185: ='FOUND DATA'!H163 | H185: ='FOUND DATA'!I163

Sheet XDataImport - WEIGHTS ONLY
A1: ='FOUND DATA'!C4 -> HW Weight | B1: ='FOUND DATA'!D4 -> # Project Assignments | C1: ='FOUND DATA'!E4 -> Project Weight | D1: ='FOUND DATA'!F4 -> # Final exam | E1: ='FOUND DATA'!G4 -> Final Weight | F1: ='FOUND DATA'!H4 -> # Other Exams
A2: ='FOUND DATA'!C5 -> 0.2 | B2: ='FOUND DATA'!D5 -> 10 | C2: ='FOUND DATA'!E5 -> 0.6 | D2: ='FOUND DATA'!F5 -> 0 | E2: ='FOUND DATA'!G5 -> 0 | F2: ='FOUND DATA'!H5 -> 0
A3: ='FOUND DATA'!C6 -> 0.32 | B3: ='FOUND DATA'!D6 -> 4 | C3: ='FOUND DATA'!E6 -> 0.16 | D3: ='FOUND DATA'!F6 -> 1 | E3: ='FOUND DATA'!G6 -> 0.2 | F3: ='FOUND DATA'!H6 -> 0
A4: ='FOUND DATA'!C7 -> 0.32 | B4: ='FOUND DATA'!D7 -> 4 | C4: ='FOUND DATA'!E7 -> 0.16 | D4: ='FOUND DATA'!F7 -> 1 | E4: ='FOUND DATA'!G7 -> 0.2 | F4: ='FOUND DATA'!H7 -> 0
A5: ='FOUND DATA'!C8 -> 0.3 | B5: ='FOUND DATA'!D8 -> 6 | C5: ='FOUND DATA'!E8 -> 0.2 | D5: ='FOUND DATA'!F8 -> 0 | E5: ='FOUND DATA'!G8 -> 0 | F5: ='FOUND DATA'!H8 -> 3
A6: ='FOUND DATA'!C9 -> 0.5 | B6: ='FOUND DATA'!D9 -> 6 | C6: ='FOUND DATA'!E9 -> 0.2 | D6: ='FOUND DATA'!F9 -> 0 | E6: ='FOUND DATA'!G9 -> 0 | F6: ='FOUND DATA'!H9 -> 3
A7: ='FOUND DATA'!C10 -> 0.36 | B7: ='FOUND DATA'!D10 -> 0 | C7: ='FOUND DATA'!E10 -> 0 | D7: ='FOUND DATA'!F10 -> 0 | E7: ='FOUND DATA'!G10 -> 0 | F7: ='FOUND DATA'!H10 -> 4
A8: ='FOUND DATA'!C11 -> 0.25 | B8: ='FOUND DATA'!D11 -> 5 | C8: ='FOUND DATA'!E11 -> 0.15 | D8: ='FOUND DATA'!F11 -> 1 | E8: ='FOUND DATA'!G11 -> 0.2 | F8: ='FOUND DATA'!H11 -> 3
A9: ='FOUND DATA'!C12 -> 0.25 | B9: ='FOUND DATA'!D12 -> 4 | C9: ='FOUND DATA'!E12 -> 0.15 | D9: ='FOUND DATA'!F12 -> 1 | E9: ='FOUND DATA'!G12 -> 0.2 | F9: ='FOUND DATA'!H12 -> 3
A10: ='FOUND DATA'!C13 -> 0.25 | B10: ='FOUND DATA'!D13 -> 9 | C10: ='FOUND DATA'!E13 -> 0.15 | D10: ='FOUND DATA'!F13 -> 1 | E10: ='FOUND DATA'!G13 -> 0.2 | F10: ='FOUND DATA'!H13 -> 3
A11: ='FOUND DATA'!C14 -> 0.25 | B11: ='FOUND DATA'!D14 -> 6 | C11: ='FOUND DATA'!E14 -> 0.15 | D11: ='FOUND DATA'!F14 -> 1 | E11: ='FOUND DATA'!G14 -> 0.2 | F11: ='FOUND DATA'!H14 -> 3
A12: ='FOUND DATA'!C15 -> 0.25 | B12: ='FOUND DATA'!D15 -> 1 | C12: ='FOUND DATA'!E15 -> 0.1 | D12: ='FOUND DATA'!F15 -> 1 | E12: ='FOUND DATA'!G15 -> 0.2 | F12: ='FOUND DATA'!H15 -> 3
... A105: ='FOUND DATA'!C108 -> END | B105: ='FOUND DATA'!D108 -> END | C105: ='FOUND DATA'!E108 -> END | D105: ='FOUND DATA'!F108 -> END | E105: ='FOUND DATA'!G108 -> END | F105: ='FOUND DATA'!H108 -> END
A124: ='FOUND DATA'!C126 | B124: ='FOUND DATA'!E126 | C124: ='FOUND DATA'!G126 | D124: ='FOUND DATA'!I126 | E124: ='FOUND DATA'!K126 | F124: ='FOUND DATA'!L126
A125: ='FOUND DATA'!C127 | B125: ='FOUND DATA'!E127 | C125: ='FOUND DATA'!G127 | D125: ='FOUND DATA'!I127 | E125: ='FOUND DATA'!K127 | F125: ='FOUND DATA'!L127
A126: ='FOUND DATA'!C128 | B126: ='FOUND DATA'!E128 | C126: ='FOUND DATA'!G128 | D126: ='FOUND DATA'!I128 | E126: ='FOUND DATA'!K128 | F126: ='FOUND DATA'!L128
A127: ='FOUND DATA'!C129 | B127: ='FOUND DATA'!E129 | C127: ='FOUND DATA'!G129 | D127: ='FOUND DATA'!I129 | E127: ='FOUND DATA'!K129 | F127: ='FOUND DATA'!L129
A128: ='FOUND DATA'!C130 | B128: ='FOUND DATA'!E130 | C128: ='FOUND DATA'!G130 | D128: ='FOUND DATA'!I130 | E128: ='FOUND DATA'!K130 | F128: ='FOUND DATA'!L130
A129: ='FOUND DATA'!C111 | B129: ='FOUND DATA'!E111 | C129: ='FOUND DATA'!G111 | D129: ='FOUND DATA'!I111 | E129: ='FOUND DATA'!K111 | F129: ='FOUND DATA'!L111
A130: ='FOUND DATA'!C112 | B130: ='FOUND DATA'!E112 | C130: ='FOUND DATA'!G112 | D130: ='FOUND DATA'!I112 | E130: ='FOUND DATA'!K112 | F130: ='FOUND DATA'!L112
A131: ='FOUND DATA'!C113 | B131: ='FOUND DATA'!E113 | C131: ='FOUND DATA'!G113 | D131: ='FOUND DATA'!I113 | E131: ='FOUND DATA'!K113 | F131: ='FOUND DATA'!L113
A132: ='FOUND DATA'!C114 | B132: ='FOUND DATA'!E114 | C132: ='FOUND DATA'!G114 | D132: ='FOUND DATA'!I114 | E132: ='FOUND DATA'!K114 | F132: ='FOUND DATA'!L114
A146: ='FOUND DATA'!C124 | B146: ='FOUND DATA'!E124 | C146: ='FOUND DATA'!G124 | D146: ='FOUND DATA'!I124 | E146: ='FOUND DATA'!K124 | F146: ='FOUND DATA'!L124
A147: ='FOUND DATA'!C125 | B147: ='FOUND DATA'!E125 | C147: ='FOUND DATA'!G125 | D147: ='FOUND DATA'!I125 | E147: ='FOUND DATA'!K125 | F147: ='FOUND DATA'!L125
A148: ='FOUND DATA'!C126 | B148: ='FOUND DATA'!E126 | C148: ='FOUND DATA'!G126 | D148: ='FOUND DATA'!I126 | E148: ='FOUND DATA'!K126 | F148: ='FOUND DATA'!L126
A149: ='FOUND DATA'!C127 | B149: ='FOUND DATA'!E127 | C149: ='FOUND DATA'!G127 | D149: ='FOUND DATA'!I127 | E149: ='FOUND DATA'!K127 | F149: ='FOUND DATA'!L127
A150: ='FOUND DATA'!C128 | B150: ='FOUND DATA'!E128 | C150: ='FOUND DATA'!G128 | D150: ='FOUND DATA'!I128 | E150: ='FOUND DATA'!K128 | F150: ='FOUND DATA'!L128
A151: ='FOUND DATA'!C129 | B151: ='FOUND DATA'!E129 | C151: ='FOUND DATA'!G129 | D151: ='FOUND DATA'!I129 | E151: ='FOUND DATA'!K129 | F151: ='FOUND DATA'!L129
A152: ='FOUND DATA'!C130 | B152: ='FOUND DATA'!E130 | C152: ='FOUND DATA'!G130 | D152: ='FOUND DATA'!I130 | E152: ='FOUND DATA'!K130 | F152: ='FOUND DATA'!L130
A153: ='FOUND DATA'!C131 | B153: ='FOUND DATA'!E131 | C153: ='FOUND DATA'!G131 | D153: ='FOUND DATA'!I131 | E153: ='FOUND DATA'!K131 | F153: ='FOUND DATA'!L131
A154: ='FOUND DATA'!C132 | B154: ='FOUND DATA'!E132 | C154: ='FOUND DATA'!G132 | D154: ='FOUND DATA'!I132 | E154: ='FOUND DATA'!K132 | F154: ='FOUND DATA'!L132
A155: ='FOUND DATA'!C133 | B155: ='FOUND DATA'!E133 | C155: ='FOUND DATA'!G133 | D155: ='FOUND DATA'!I133 | E155: ='FOUND DATA'!K133 | F155: ='FOUND DATA'!L133
A156: ='FOUND DATA'!C134 | B156: ='FOUND DATA'!E134 | C156: ='FOUND DATA'!G134 | D156: ='FOUND DATA'!I134 | E156: ='FOUND DATA'!K134 | F156: ='FOUND DATA'!L134
A157: ='FOUND DATA'!C135 | B157: ='FOUND DATA'!E135 | C157: ='FOUND DATA'!G135 | D157: ='FOUND DATA'!I135 | E157: ='FOUND DATA'!K135 | F157: ='FOUND DATA'!L135
... A185: ='FOUND DATA'!C163 | B185: ='FOUND DATA'!E163 | C185: ='FOUND DATA'!G163 | D185: ='FOUND DATA'!I163 | E185: ='FOUND DATA'!K163 | F185: ='FOUND DATA'!L163

Sheet YDataImport - DISTRIBUTION
A1: ='FOUND DATA'!N4 -> Class F | B1: ='FOUND DATA'!O4 -> Class D | C1: ='FOUND DATA'!P4 -> Class C | D1: ='FOUND DATA'!Q4 -> Class B | E1: ='FOUND DATA'!R4 -> Class A
A2: ='FOUND DATA'!N5 -> 0.48 | B2: ='FOUND DATA'!O5 -> 1.58 | C2: ='FOUND DATA'!P5 -> 4.11 | D2: ='FOUND DATA'!Q5 -> 15.03 | E2: ='FOUND DATA'!R5 -> 78.8
A3: ='FOUND DATA'!N6 -> 1.2 | B3: ='FOUND DATA'!O6 -> 4.82 | C3: ='FOUND DATA'!P6 -> 19.28 | D3: ='FOUND DATA'!Q6 -> 39.76 | E3: ='FOUND DATA'!R6 -> 34.94
A4: ='FOUND DATA'!N7 -> 0 | B4: ='FOUND DATA'!O7 -> 5.97 | C4: ='FOUND DATA'!P7 -> 16.42 | D4: ='FOUND DATA'!Q7 -> 41.79 | E4: ='FOUND DATA'!R7 -> 35.82
A5: ='FOUND DATA'!N8 -> 3.17 | B5: ='FOUND DATA'!O8 -> 6.35 | C5: ='FOUND DATA'!P8 -> 16.67 | D5: ='FOUND DATA'!Q8 -> 48.41 | E5: ='FOUND DATA'!R8 -> 25.4
A6: ='FOUND DATA'!N9 -> 3.43 | B6: ='FOUND DATA'!O9 -> 2.05 | C6: ='FOUND DATA'!P9 -> 32.19 | D6: ='FOUND DATA'!Q9 -> 45.21 | E6: ='FOUND DATA'!R9 -> 17.12
A7: ='FOUND DATA'!N10 -> 5.63 | B7: ='FOUND DATA'!O10 -> 3.52 | C7: ='FOUND DATA'!P10 -> 17.61 | D7: ='FOUND DATA'!Q10 -> 39.44 | E7: ='FOUND DATA'!R10 -> 33.8
A8: ='FOUND DATA'!N11 -> 5.36 | B8: ='FOUND DATA'!O11 -> 6.55 | C8: ='FOUND DATA'!P11 -> 19.64 | D8: ='FOUND DATA'!Q11 -> 35.12 | E8: ='FOUND DATA'!R11 -> 33.33
A9: ='FOUND DATA'!N12 -> 7.5 | B9: ='FOUND DATA'!O12 -> 6.25 | C9: ='FOUND DATA'!P12 -> 22.5 | D9: ='FOUND DATA'!Q12 -> 34.38 | E9: ='FOUND DATA'!R12 -> 29.37
A10: ='FOUND DATA'!N13 -> 7.1 | B10: ='FOUND DATA'!O13 -> 7.1 | C10: ='FOUND DATA'!P13 -> 12.26 | D10: ='FOUND DATA'!Q13 -> 34.19 | E10: ='FOUND DATA'!R13 -> 39.35
A11: ='FOUND DATA'!N14 -> 6.56 | B11: ='FOUND DATA'!O14 -> 2.19 | C11: ='FOUND DATA'!P14 -> 10.95 | D11: ='FOUND DATA'!Q14 -> 35.77 | E11: ='FOUND DATA'!R14 -> 44.53
A12: ='FOUND DATA'!N15 -> 1.55 | B12: ='FOUND DATA'!O15 -> 0.78 | C12: ='FOUND DATA'!P15 -> 17.83 | D12: ='FOUND DATA'!Q15 -> 41.86 | E12: ='FOUND DATA'!R15 -> 37.98
... A105: ='FOUND DATA'!N108 -> END | B105: ='FOUND DATA'!O108 -> END | C105: ='FOUND DATA'!P108 -> END | D105: ='FOUND DATA'!Q108 -> END | E105: ='FOUND DATA'!R108 -> END
A122: ='FOUND DATA'!N124 | B122: ='FOUND DATA'!O124 | C122: ='FOUND DATA'!P124 | D122: ='FOUND DATA'!Q124 | E122: ='FOUND DATA'!R124
A123: ='FOUND DATA'!N125 | B123: ='FOUND DATA'!O125 | C123: ='FOUND DATA'!P125 | D123: ='FOUND DATA'!Q125 | E123: ='FOUND DATA'!R125
A124: ='FOUND DATA'!N126 | B124: ='FOUND DATA'!O126 | C124: ='FOUND DATA'!P126 | D124: ='FOUND DATA'!Q126 | E124: ='FOUND DATA'!R126
A125: ='FOUND DATA'!N127 | B125: ='FOUND DATA'!O127 | C125: ='FOUND DATA'!P127 | D125: ='FOUND DATA'!Q127 | E125: ='FOUND DATA'!R127
A126: ='FOUND DATA'!N128 | B126: ='FOUND DATA'!O128 | C126: ='FOUND DATA'!P128 | D126: ='FOUND DATA'!Q128 | E126: ='FOUND DATA'!R128
